Workbook

Sheet 메뉴목록
A2: 모키 커피바 메뉴 데이터
A3: v4 · 33개 메뉴 · 커피 12 / 차·논커피 7 / 디저트 5 / 주류 6 / 원두 3
A5: 메뉴 ID | B5: 메뉴명 | C5: 분류 | D5: 영문명 | E5: 별칭 | F5: 설명 | G5: 원재료(가상 레시피) | H5: 알레르기 유발 재료 | I5: 단맛 1~5 | J5: 산미 1~5 | K5: 쓴맛 1~5 | L5: 바디 1~5 | M5: 추천 태그 | N5: 페어링 ID | O5: 참고 원메뉴 행 | P5: 설계 참고 | Q5: 데이터 성격 | R5: 별칭에 포함된 요청 | S5: 맛 점수 기준 | T5: 대표 이미지 경로 | U5: 사진 기준 주문 단위 | V5: 사진 설명 | W5: 이미지 구분 | X5: 주류 구분 | Y5: 직원 확인 | Z5: 판매 단위 | AA5: 식감
A6: M01 | B6: 에스프레소 | C6: 커피 | D6: Espresso | E6: 에쏘, 더블 에스프레소, Espresso | F6: 작은 잔에 담아 진한 향과 여운을 즐기는 더블 에스프레소입니다. | G6: 커피 원두, 물 | H6: 레시피상 지정 재료 없음 | I6: 1 | J6: 1 | K6: 5 | L6: 5 | M6: 진한 커피, 무가당 | N6: M18, M28 | P6: R1 | Q6: 시연용 가상 설정 | R6: 별도 지정 없음 | S6: 하우스 원두·기본 레시피 기준. 원두 변경 시 선택 원두 설명 참조 | T6: images/M01.png | U6: M01-HOT-ONE | V6: 에스프레소, HOT / 음료 1잔, 대표 AI 연출 이미지 | W6: AI 연출 이미지 | X6: 주류 미첨가 레시피 | Y6: 해당 없음 | Z6: 음료 1잔 | AA6: 진하고 묵직함
A7: M02 | B7: 아메리카노 | C7: 커피 | D7: Americano | E7: 아아, 아이스 아메리카노, 뜨아, Americano, iced americano, hot americano | F7: 에스프레소에 물을 더한 깔끔한 블랙커피입니다. 선택한 원두의 향과 맛을 편하게 즐길 수 있습니다. | G7: 커피 원두, 물 | H7: 레시피상 지정 재료 없음 | I7: 1 | J7: 1 | K7: 3 | L7: 2 | M7: 블랙커피, 무가당 | N7: M18, M20 | P7: R1, R2 | Q7: 시연용 가상 설정 | R7: 아아 → ICED 아이스 아메리카노 → ICED 뜨아 → HOT iced americano → ICED hot americano → HOT | S7: 하우스 원두·기본 레시피 기준. 원두 변경 시 선택 원두 설명 참조 | T7: images/M02.png | U7: M02-ICED-S | V7: 아메리카노, ICED / 음료 1잔, 대표 AI 연출 이미지 | W7: AI 연출 이미지 | X7: 주류 미첨가 레시피 | Y7: 해당 없음 | Z7: 음료 1잔 | AA7: 깔끔하고 가벼움
A8: M03 | B8: 카페 라떼 | C8: 커피 | D8: Caffe Latte | E8: 카페라떼, 라떼, 디카페인 카페라떼, Caffe Latte, latte, iced latte, decaf latte, decaf iced latte | F8: 에스프레소와 우유가 부드럽게 어우러지는 기본 라떼입니다. | G8: 커피 원두, 물, 우유 | H8: 우유 | I8: 2 | J8: 1 | K8: 2 | L8: 3 | M8: 부드러움, 우유 | N8: M18, M28 | O8: 87, 111 | P8: R1 | Q8: 시연용 가상 설정 | R8: 디카페인 카페라떼 → B03 iced latte → ICED decaf latte → B03 decaf iced latte → ICED B03 | S8: 하우스 원두·기본 레시피 기준. 원두 변경 시 선택 원두 설명 참조 | T8: images/M03.png | U8: M03-HOT-S | V8: 카페 라떼, HOT / 음료 1잔, 대표 AI 연출 이미지 | W8: AI 연출 이미지 | X8: 주류 미첨가 레시피 | Y8: 해당 없음 | Z8: 음료 1잔 | AA8: 부드러움
A9: M04 | B9: 카푸치노 | C9: 커피 | D9: Cappuccino | E9: 카푸치노, Cappuccino | F9: 라떼보다 우유의 비중이 낮고, 풍성한 우유 거품이 올라가는 따뜻한 커피입니다. | G9: 커피 원두, 물, 우유 | H9: 우유 | I9: 2 | J9: 1 | K9: 3 | L9: 3 | M9: 거품, 따뜻함 | N9: M28, M29 | P9: R1 | Q9: 시연용 가상 설정 | R9: 별도 지정 없음 | S9: 하우스 원두·기본 레시피 기준. 원두 변경 시 선택 원두 설명 참조 | T9: images/M04.png | U9: M04-HOT-ONE | V9: 카푸치노, HOT / 음료 1잔, 대표 AI 연출 이미지 | W9: AI 연출 이미지 | X9: 주류 미첨가 레시피 | Y9: 해당 없음 | Z9: 음료 1잔 | AA9: 풍성한 거품
A10: M05 | B10: 플랫화이트 | C10: 커피 | D10: Flat White | E10: 플랫 화이트, 플랫화이트, Flat White | F10: 작은 잔에 에스프레소와 고운 우유 거품을 담아 커피 맛이 또렷한 메뉴입니다. | G10: 커피 원두, 물, 우유 | H10: 우유 | I10: 2 | J10: 1 | K10: 3 | L10: 4 | M10: 작은 잔, 진한 라떼 | N10: M28, M20 | P10: R1 | Q10: 시연용 가상 설정 | R10: 별도 지정 없음 | S10: 하우스 원두·기본 레시피 기준. 원두 변경 시 선택 원두 설명 참조 | T10: images/M05.png | U10: M05-HOT-ONE | V10: 플랫화이트, HOT / 음료 1잔, 대표 AI 연출 이미지 | W10: AI 연출 이미지 | X10: 주류 미첨가 레시피 | Y10: 해당 없음 | Z10: 음료 1잔 | AA10: 고운 거품
A11: M06 | B11: 바닐라 라떼 | C11: 커피 | D11: Vanilla Latte | E11: 바닐라라떼, 바라, 디카페인 바닐라라떼, Vanilla Latte | F11: 바닐라 향과 우유의 부드러움이 어우러지는 달콤한 라떼입니다. 덜 달게 드시려면 시럽을 절반으로 선택할 수 있습니다. | G11: 커피 원두, 물, 우유, 바닐라 시럽(설탕·물·바닐라향, 알코올 무첨가 설정) | H11: 우유 | I11: 4 | J11: 1 | K11: 2 | L11: 3 | M11: 달콤함, 바닐라 | N11: M18, M20 | O11: 91, 113 | P11: R1 | Q11: 시연용 가상 설정 | R11: 디카페인 바닐라라떼 → B03 | S11: 하우스 원두·기본 레시피 기준. 원두 변경 시 선택 원두 설명 참조 | T11: images/M06.png | U11: M06-ICED-S | V11: 바닐라 라떼, ICED / 음료 1잔, 대표 AI 연출 이미지 | W11: AI 연출 이미지 | X11: 주류 미첨가 레시피 | Y11: 해당 없음 | Z11: 음료 1잔 | AA11: 부드럽고 달콤함
A12: M07 | B12: 고운결 크림 라떼 | C12: 커피 | D12: Goungyeol Cream Latte | E12: 고운결 라떼, 크림 라떼, 디카페인 고운결 라떼, Goungyeol Cream Latte | F12: 작은 잔에 담은 달콤한 크림과 진한 커피를 함께 즐기는 시그니처 라떼입니다. | G12: 커피 원두, 물, 우유, 생크림(우유), 설탕 | H12: 우유 | I12: 4 | J12: 1 | K12: 2 | L12: 5 | M12: 크림, 시그니처 | N12: M28, M29 | O12: 15, 108 | P12: R1 | Q12: 시연용 가상 설정 | R12: 디카페인 고운결 라떼 → B03 | S12: 하우스 원두·기본 레시피 기준. 원두 변경 시 선택 원두 설명 참조 | T12: images/M07.png | U12: M07-ICED-ONE | V12: 고운결 크림 라떼, ICED / 음료 1잔, 대표 AI 연출 이미지 | W12: AI 연출 이미지 | X12: 주류 미첨가 레시피 | Y12: 해당 없음 | Z12: 음료 1잔 | AA12: 진하고 크리미함
A13: M08 | B13: 다크 카페 모카 | C13: 커피 | D13: Dark Caffe Mocha | E13: 카페모카, 모카, 디카페인 카페모카, Dark Caffe Mocha | F13: 카카오의 쌉싸름한 맛과 에스프레소가 어우러지는 진한 모카입니다. | G13: 커피 원두, 물, 우유, 초콜릿 소스(코코아·설탕·대두레시틴) | H13: 우유, 대두 | I13: 4 | J13: 1 | K13: 3 | L13: 4 | M13: 초콜릿, 달콤함 | N13: M18, M20 | O13: 93, 115 | P13: R1 | Q13: 시연용 가상 설정 | R13: 디카페인 카페모카 → B03 | S13: 하우스 원두·기본 레시피 기준. 원두 변경 시 선택 원두 설명 참조 | T13: images/M08.png | U13: M08-HOT-ONE | V13: 다크 카페 모카, HOT / 음료 1잔, 대표 AI 연출 이미지 | W13: AI 연출 이미지 | X13: 주류 미첨가 레시피 | Y13: 해당 없음 | Z13: 음료 1잔 | AA13: 진한 초콜릿 풍미
A14: M09 | B14: 콜드브루 | C14: 커피 | D14: Cold Brew | E14: 콜드 브루, 더치커피, Cold Brew | F14: 하우스 원두로 미리 추출한 부드러운 풍미의 차가운 블랙커피입니다. | G14: 커피 원두, 물 | H14: 레시피상 지정 재료 없음 | I14: 1 | J14: 1 | K14: 2 | L14: 3 | M14: 차가움, 블랙커피 | N14: M18, M21 | P14: R2, R3 | Q14: 시연용 가상 설정 | R14: 별도 지정 없음 | S14: 기본 레시피 기준 | T14: images/M09.png | U14: M09-ICED-ONE | V14: 콜드브루, ICED / 음료 1잔, 대표 AI 연출 이미지 | W14: AI 연출 이미지 | X14: 주류 미첨가 레시피 | Y14: 해당 없음 | Z14: 음료 1잔 | AA14: 부드럽고 깔끔함
A15: M10 | B15: 콜드브루 라떼 | C15: 커피 | D15: Cold Brew Latte | E15: 콜드브루라떼, 콜드 브루 라떼, Cold Brew Latte | F15: 하우스 콜드브루에 우유를 더한 부드러운 아이스 커피입니다. | G15: 커피 원두, 물, 우유 | H15: 우유 | I15: 2 | J15: 1 | K15: 2 | L15: 3 | M15: 차가움, 부드러움 | N15: M28, M29 | O15: 98 | P15: R2 | Q15: 시연용 가상 설정 | R15: 별도 지정 없음 | S15: 기본 레시피 기준 | T15: images/M10.png | U15: M10-ICED-ONE | V15: 콜드브루 라떼, ICED / 음료 1잔, 대표 AI 연출 이미지 | W15: AI 연출 이미지 | X15: 주류 미첨가 레시피 | Y15: 해당 없음 | Z15: 음료 1잔 | AA15: 부드러운 우유 질감
A16: M11 | B16: 에티오피아 필터커피 | C16: 커피 | D16: Ethiopia Filter Coffee | E16: 드립커피, 핸드드립, 산미 커피, 에티오피아, Ethiopia Filter Coffee | F16: 감귤과 꽃을 떠올리게 하는 향, 산뜻한 산미가 특징인 필터커피입니다. | G16: 커피 원두, 물 | H16: 레시피상 지정 재료 없음 | I16: 2 | J16: 4 | K16: 2 | L16: 2 | M16: 산뜻함, 필터커피 | N16: M28, M20 | P16: R3, R5 | Q16: 시연용 가상 설정 | R16: 별도 지정 없음 | S16: 기본 레시피 기준 | T16: images/M11.png | U16: M11-HOT-ONE | V16: 에티오피아 필터커피, HOT / 음료 1잔, 대표 AI 연출 이미지 | W16: AI 연출 이미지 | X16: 주류 미첨가 레시피 | Y16: 해당 없음 | Z16: 음료 1잔 | AA16: 맑고 가벼움
A17: M12 | B17: 디카페인 필터커피 | C17: 커피 | D17: Decaf Filter Coffee | E17: 디카페인 드립, 디카페인 핸드드립, Decaf Filter Coffee | F17: 캐러멜을 떠올리게 하는 향과 부드러운 여운의 콜롬비아 디카페인 필터커피입니다. | G17: 디카페인 커피 원두, 물 | H17: 레시피상 지정 재료 없음 | I17: 2 | J17: 2 | K17: 2 | L17: 3 | M17: 디카페인, 필터커피 | N17: M18, M29 | P17: R4, R5 | Q17: 시연용 가상 설정 | R17: 별도 지정 없음 | S17: 기본 레시피 기준 | T17: images/M12.png | U17: M12-HOT-ONE | V17: 디카페인 필터커피, HOT / 음료 1잔, 대표 AI 연출 이미지 | W17: AI 연출 이미지 | X17: 주류 미첨가 레시피 | Y17: 해당 없음 | Z17: 음료 1잔 | AA17: 맑고 부드러움
A18: M13 | B18: 말차 라떼 | C18: 차/논커피 | D18: Matcha Latte | E18: 말차라떼, 녹차라떼, Matcha Latte | F18: 말차의 쌉싸름한 맛과 우유의 부드러움이 어우러지는 음료입니다. | G18: 말차 분말, 우유, 설탕 | H18: 우유 | I18: 3 | J18: 1 | K18: 3 | L18: 3 | M18: 말차, 논커피 | N18: M28, M20 | O18: 132 | P18: R1 | Q18: 시연용 가상 설정 | R18: 별도 지정 없음 | S18: 기본 레시피 기준 | T18: images/M13.png | U18: M13-ICED-ONE | V18: 말차 라떼, ICED / 음료 1잔, 대표 AI 연출 이미지 | W18: AI 연출 이미지 | X18: 주류 미첨가 레시피 | Y18: 해당 없음 | Z18: 음료 1잔 | AA18: 부드럽고 쌉싸름함
A19: M14 | B19: 초코 라떼 | C19: 차/논커피 | D19: Chocolate Latte | E19: 초코라떼, 핫초코, 코코아, Chocolate Latte, hot chocolate | F19: 진한 코코아 풍미를 담은 달콤한 우유 음료입니다. | G19: 우유, 초콜릿 소스(코코아·설탕·대두레시틴) | H19: 우유, 대두 | I19: 4 | J19: 1 | K19: 2 | L19: 4 | M19: 초콜릿, 논커피 | N19: M18, M29 | O19: 134 | P19: R1 | Q19: 시연용 가상 설정 | R19: 핫초코 → HOT hot chocolate → HOT | S19: 기본 레시피 기준 | T19: images/M14.png | U19: M14-HOT-ONE | V19: 초코 라떼, HOT / 음료 1잔, 대표 AI 연출 이미지 | W19: AI 연출 이미지 | X19: 주류 미첨가 레시피 | Y19: 해당 없음 | Z19: 음료 1잔 | AA19: 진하고 부드러움
A20: M15 | B20: 보성 홍차 밀크티 | C20: 차/논커피 | D20: Boseong Black Milk Tea | E20: 밀크티, 홍차라떼, 보성 밀크티, Boseong Black Milk Tea | F20: 보성 홍차의 향과 우유의 부드러움을 함께 즐기는 밀크티입니다. | G20: 보성산 홍차, 물, 우유, 설탕 | H20: 우유 | I20: 3 | J20: 2 | K20: 2 | L20: 3 | M20: 홍차, 논커피 | N20: M28, M20 | O20: 136 | P20: R1 | Q20: 시연용 가상 설정 | R20: 별도 지정 없음 | S20: 기본 레시피 기준 | T20: images/M15.png | U20: M15-ICED-ONE | V20: 보성 홍차 밀크티, ICED / 음료 1잔, 대표 AI 연출 이미지 | W20: AI 연출 이미지 | X20: 주류 미첨가 레시피 | Y20: 해당 없음 | Z20: 음료 1잔 | AA20: 부드럽고 향긋함
A21: M16 | B21: 유자티 | C21: 차/논커피 | D21: Yuja Tea — Korean Citrus | E21: 유자차, 유자 티, Yuja Tea — Korean Citrus, Yuja Tea, yuja tea, yuzu tea | F21: 유자청을 풀어 만든 새콤달콤한 음료입니다. 찻잎과 커피는 넣지 않습니다. | G21: 유자청(유자·설탕), 물 | H21: 레시피상 지정 재료 없음 | I21: 4 | J21: 3 | K21: 1 | L21: 1 | M21: 새콤달콤함, 유자 | N21: M18, M28 | P21: R5 | Q21: 시연용 가상 설정 | R21: 별도 지정 없음 | S21: 기본 레시피 기준 | T21: images/M16.png | U21: M16-ICED-ONE | V21: 유자티, ICED / 음료 1잔, 대표 AI 연출 이미지 | W21: AI 연출 이미지 | X21: 주류 미첨가 레시피 | Y21: 해당 없음 | Z21: 음료 1잔 | AA21: 새콤달콤한 과육감
A22: M17 | B22: 루이보스티 | C22: 차/논커피 | D22: Rooibos Tea | E22: 루이보스, 루이보스 차, 허브티, Rooibos Tea | F22: 루이보스 잎을 우려 만든 담백한 차입니다. 시럽과 우유는 넣지 않습니다. | G22: 루이보스 잎, 물 | H22: 레시피상 지정 재료 없음 | I22: 1 | J22: 1 | K22: 1 | L22: 1 | M22: 무가당, 담백함 | N22: M28, M29 | P22: R5 | Q22: 시연용 가상 설정 | R22: 별도 지정 없음 | S22: 기본 레시피 기준 | T22: images/M17.png | U22: M17-HOT-ONE | V22: 루이보스티, HOT / 음료 1잔, 대표 AI 연출 이미지 | W22: AI 연출 이미지 | X22: 주류 미첨가 레시피 | Y22: 해당 없음 | Z22: 음료 1잔 | AA22: 맑고 담백함
A23: M26 | B23: 오미자차 | C23: 차/논커피 | D23: Omija Tea — Five-Flavor Berry | E23: 오미자차, omija tea, five flavor berry tea, Omija Tea — Five-Flavor Berry, Omija Tea, iced omija tea | F23: 오미자청을 물에 풀어 만든 새콤달콤한 차입니다. 붉은 빛과 산뜻한 과일 향을 즐길 수 있습니다. | G23: 오미자청(오미자·설탕), 물 | H23: 레시피상 지정 재료 없음 | I23: 3 | J23: 4 | K23: 1 | L23: 2 | M23: 맑고 가벼움 | N23: M28, M29 | P23: R6 | Q23: 시연용 가상 설정 | R23: iced omija tea → ICED | S23: 기본 레시피 기준 | T23: images/M26.png | U23: M26-ICED-ONE | V23: 오미자차, ICED / 음료 1잔, 대표 AI 연출 이미지 | W23: AI 연출 이미지 | X23: 주류 미첨가 레시피 | Y23: 해당 없음 | Z23: 음료 1잔 | AA23: 맑고 가벼움
A24: M27 | B24: 대추생강차 | C24: 차/논커피 | D24: Daechu Saenggang Tea — Jujube & Ginger | E24: 대추차, 생강차, 대추생강차, jujube ginger tea, Daechu Saenggang Tea — Jujube & Ginger, Daechu Saenggang Tea | F24: 대추의 은은한 단맛에 생강의 알싸한 향을 더한 차입니다. 얇게 썬 대추 두 조각을 띄워 제공합니다. | G24: 대추, 생강, 꿀, 물 | H24: 레시피상 지정 재료 없음 | I24: 3 | J24: 1 | K24: 1 | L24: 3 | M24: 은은하게 진함 | N24: M28, M18 | P24: R6 | Q24: 시연용 가상 설정 | R24: 별도 지정 없음 | S24: 기본 레시피 기준 | T24: images/M27.png | U24: M27-HOT-ONE | V24: 대추생강차, HOT / 음료 1잔, 대표 AI 연출 이미지 | W24: AI 연출 이미지 | X24: 주류 미첨가 레시피 | Y24: 해당 없음 | Z24: 음료 1잔 | AA24: 은은하게 진함
A25: M18 | B25: 버터 소금빵 | C25: 디저트 | D25: Butter Salt Bread | E25: 소금빵, 버터소금빵, Butter Salt Bread | F25: 고소한 버터 향과 짭짤한 맛이 어우러지는 소금빵 한 개입니다. 따뜻하게 데워 드릴 수 있습니다. | G25: 밀가루, 버터(우유), 우유, 설탕, 효모, 소금 | H25: 밀, 우유 | I25: 2 | J25: 1 | K25: 1 | L25: 3 | M25: 짭짤함, 베이커리 | N25: M02, M03 | O25: 70 | P25: R1 | Q25: 시연용 가상 설정 | R25: 별도 지정 없음 | S25: 기본 레시피 기준 | T25: images/M18.png | U25: M18-NA-ONE | V25: 버터 소금빵, 빵 1개, 대표 AI 연출 이미지 | W25: AI 연출 이미지 | X25: 주류 미첨가 레시피 | Y25: 해당 없음 | Z25: 빵 1개 | AA25: 부드러운 속과 얇은 껍질
A26: M20 | B26: 바스크 치즈케이크 | C26: 디저트 | D26: Basque Cheesecake | E26: 치즈케이크, 바스크 치즈, Basque Cheesecake | F26: 겉면을 진하게 구워 고소한 향과 부드러운 치즈 풍미를 살린 케이크 한 조각입니다. | G26: 크림치즈(우유), 생크림(우유), 계란, 설탕, 밀가루 | H26: 우유, 계란, 밀 | I26: 4 | J26: 2 | K26: 1 | L26: 5 | M26: 치즈, 진한 디저트 | N26: M02, M11 | O26: 52 | P26: R1 | Q26: 시연용 가상 설정 | R26: 별도 지정 없음 | S26: 기본 레시피 기준 | T26: images/M20.png | U26: M20-NA-ONE | V26: 바스크 치즈케이크, 케이크 1조각, 대표 AI 연출 이미지 | W26: AI 연출 이미지 | X26: 주류 미첨가 레시피 | Y26: 해당 없음 | Z26: 케이크 1조각 | AA26: 진하고 크리미함
A27: M21 | B27: 티라미수 컵 | C27: 디저트 | D27: Tiramisu Cup | E27: 티라미수, 티라미수 컵, Tiramisu Cup | F27: 마스카르포네 크림과 커피에 적신 시트를 층층이 담은 개인용 컵 디저트입니다. 이 레시피에는 술을 넣지 않습니다. | G27: 마스카르포네(우유), 생크림(우유), 계란, 밀가루, 설탕, 커피, 코코아 | H27: 우유, 계란, 밀 | I27: 4 | J27: 1 | K27: 2 | L27: 4 | M27: 커피 디저트, 컵 디저트 | N27: M09, M02 | O27: 53 | P27: R1 | Q27: 시연용 가상 설정 | R27: 별도 지정 없음 | S27: 기본 레시피 기준 | T27: images/M21.png | U27: M21-NA-ONE | V27: 티라미수 컵, 디저트 1컵, 대표 AI 연출 이미지 | W27: AI 연출 이미지 | X27: 주류 미첨가 레시피 | Y27: 해당 없음 | Z27: 디저트 1컵 | AA27: 촉촉한 시트와 크림
A28: M28 | B28: 약과 2개 | C28: 디저트 | D28: Yakgwa — Honey Cookies (2 pcs) | E28: 약과, yakgwa, Korean honey cookies, Yakgwa — Honey Cookies (2 pcs), Yakgwa | F28: 꿀과 조청의 달콤함을 담은 작은 약과 두 개입니다. 꽃 모양의 과자는 겉이 윤기 있고 속은 촉촉하고 쫀득합니다. | G28: 밀가루, 조청(쌀·보리 엿기름), 꿀, 참기름, 식용유, 생강즙 | H28: 밀, 보리, 참깨 | I28: 4 | J28: 1 | K28: 1 | L28: 4 | M28: 촉촉하고 쫀득함 | N28: M01, M26, M27 | P28: R6 | Q28: 시연용 가상 설정 | R28: 별도 지정 없음 | S28: 기본 레시피 기준 | T28: images/M28.png | U28: M28-NA-ONE | V28: 약과 2개, 약과 2개 1접시, 대표 AI 연출 이미지 | W28: AI 연출 이미지 | X28: 주류 미첨가 레시피 | Y28: 해당 없음 | Z28: 약과 2개 1접시 | AA28: 촉촉하고 쫀득함
A29: M29 | B29: 쑥인절미 4개 | C29: 디저트 | D29: Ssuk Injeolmi — Mugwort Rice Cakes (4 pcs) | E29: 쑥떡, 인절미, ssuk injeolmi, mugwort rice cakes, Ssuk Injeolmi — Mugwort Rice Cakes (4 pcs), Ssuk Injeolmi | F29: 쑥을 넣은 찹쌀떡에 볶은 콩가루를 묻힌 인절미 네 개입니다. 쑥의 풀 향과 고소한 콩가루, 쫀득한 식감이 어우러집니다. | G29: 찹쌀, 쑥, 볶은 콩가루(대두), 설탕, 소금 | H29: 대두 | I29: 2 | J29: 1 | K29: 2 | L29: 4 | M29: 부드럽고 쫀득함 | N29: M12, M26, M15 | P29: R6 | Q29: 시연용 가상 설정 | R29: 별도 지정 없음 | S29: 기본 레시피 기준 | T29: images/M29.png | U29: M29-NA-ONE | V29: 쑥인절미 4개, 떡 4개 1접시, 대표 AI 연출 이미지 | W29: AI 연출 이미지 | X29: 주류 미첨가 레시피 | Y29: 해당 없음 | Z29: 떡 4개 1접시 | AA29: 부드럽고 쫀득함
A30: M32 | B30: 유자 소주 하이볼 | C30: 주류 | D30: Yuja Soju Highball | E30: 유자 하이볼, 유자 소주 하이볼, yuja soju highball, yuzu soju highball, Yuja Soju Highball, 하이볼, highball | F30: 유자청과 소주에 탄산수를 더한 산뜻한 칵테일입니다. 가는 유자 껍질과 얼음이 함께 들어갑니다. 주류가 포함됩니다. | G30: 소주(쌀 증류주·물, 20%), 유자청(유자·설탕), 탄산수, 얼음 | H30: 레시피상 지정 재료 없음 | I30: 3 | J30: 3 | K30: 2 | L30: 2 | M30: 가벼운 탄산 | P30: R8 | Q30: 시연용 가상 설정 | R30: 별도 지정 없음 | S30: 기본 레시피 기준 | T30: images/M32.png | U30: M32-ICED-ONE | V30: 유자 소주 하이볼, ICED / 음료 1잔, 대표 AI 연출 이미지 | W30: AI 연출 이미지 | X30: 주류 포함 | Y30: 필요 | Z30: 음료 1잔 | AA30: 가벼운 탄산
A31: M33 | B31: 오미자 소주 스프리츠 | C31: 주류 | D31: Omija Soju Spritz | E31: 오미자 칵테일, 오미자 스프리츠, omija soju spritz, omija cocktail, Omija Soju Spritz | F31: 오미자청과 소주에 탄산수를 더한 붉은빛 칵테일입니다. 새콤달콤한 맛과 가벼운 탄산을 즐길 수 있습니다. 주류가 포함됩니다. | G31: 소주(쌀 증류주·물, 20%), 오미자청(오미자·설탕), 탄산수, 얼음 | H31: 레시피상 지정 재료 없음 | I31: 3 | J31: 4 | K31: 2 | L31: 2 | M31: 산뜻한 탄산 | P31: R8 | Q31: 시연용 가상 설정 | R31: 별도 지정 없음 | S31: 기본 레시피 기준 | T31: images/M33.png | U31: M33-ICED-ONE | V31: 오미자 소주 스프리츠, ICED / 음료 1잔, 대표 AI 연출 이미지 | W31: AI 연출 이미지 | X31: 주류 포함 | Y31: 필요 | Z31: 음료 1잔 | AA31: 산뜻한 탄산
A32: M34 | B32: 위스키 하이볼 | C32: 주류 | D32: Whisky Highball | E32: 하이볼, 위스키 하이볼, whisky highball, whiskey highball, highball | F32: 위스키의 은은한 오크 향과 탄산을 즐기는 드라이한 하이볼입니다. 레몬 껍질을 곁들이며 얼음과 함께 제공합니다. | G32: 위스키(40% 설정), 탄산수, 레몬 껍질, 얼음 | H32: 레시피상 지정 재료 없음 | I32: 1 | J32: 1 | K32: 2 | L32: 2 | M32: 가볍고 청량함 | N32: M18 | Q32: 시연용 가상 설정 | R32: 별도 지정 없음 | S32: 기본 레시피 기준 | T32: images/M34.png | U32: M34-ICED-ONE | V32: 위스키 하이볼, ICED / 얼음 포함 300ml 잔, 대표 AI 연출 이미지 | W32: AI 연출 이미지 | X32: 주류 포함 | Y32: 필요 | Z32: 얼음 포함 300ml 잔 | AA32: 가볍고 청량함
A33: M35 | B33: 에스프레소 마티니 | C33: 주류 | D33: Espresso Martini | E33: 에스프레소 마티니, 커피 칵테일, espresso martini, coffee cocktail | F33: 에스프레소에 보드카와 커피 리큐르를 더한 진한 커피 칵테일입니다. 차갑게 흔든 뒤 얼음을 걸러 내고 커피 원두 3알을 올립니다. 알코올과 카페인이 모두 들어 있습니다. | G33: 보드카(40% 설정), 커피 리큐르(20% 설정; 커피·설탕·주정·물), 하우스 에스프레소, 설탕 시럽, 물(셰이킹 희석분), 장식용 커피 원두 3알 | H33: 레시피상 지정 재료 없음 | I33: 3 | J33: 1 | K33: 3 | L33: 4 | M33: 진한 커피와 부드러운 거품 | N33: M21 | P33: R11 | Q33: 시연용 가상 설정 | R33: 별도 지정 없음 | S33: 기본 레시피 기준 | T33: images/M35.png | U33: M35-ICED-ONE | V33: 에스프레소 마티니, ICED / 차갑게, 얼음 없이 120ml 1잔, 대표 AI 연출 이미지 | W33: AI 연출 이미지 | X33: 주류 포함 | Y33: 필요 | Z33: 차갑게, 얼음 없이 120ml 1잔 | AA33: 진한 커피와 부드러운 거품
A34: M36 | B34: 라거 맥주 | C34: 주류 | D34: Lager Beer | E34: 맥주, 라거, 라거 맥주, beer, lager, lager beer | F34: 깔끔한 몰트 풍미와 가벼운 쌉쌀함의 라거입니다. 330ml를 차갑게 잔에 담아 얼음 없이 제공합니다. | G34: 물, 보리 맥아, 홉, 효모 | H34: 보리 | I34: 1 | J34: 1 | K34: 2 | L34: 2 | M34: 가볍고 탄산감 있음 | N34: M18 | Q34: 시연용 가상 설정 | R34: 별도 지정 없음 | S34: 기본 레시피 기준 | T34: images/M36.png | U34: M36-ICED-ONE | V34: 라거 맥주, ICED / 차갑게, 얼음 없이 330ml 1잔, 대표 AI 연출 이미지 | W34: AI 연출 이미지 | X34: 주류 포함 | Y34: 필요 | Z34: 차갑게, 얼음 없이 330ml 1잔 | AA34: 가볍고 탄산감 있음
A35: M37 | B35: 하우스 레드와인 | C35: 주류 | D35: House Red Wine | E35: 레드와인, 와인, 하우스 와인, red wine, house red wine, wine | F35: 붉은 과일 향과 부드러운 떫은맛이 있는 드라이 레드와인입니다. 150ml 잔 단위로 제공하며 얼음이나 온도 변경 옵션은 없습니다. | G35: 적포도 발효액, 아황산류(보존제) | H35: 아황산류 | I35: 1 | J35: 3 | K35: 2 | L35: 3 | M35: 부드러운 바디와 가벼운 떫은맛 | N35: M20 | Q35: 시연용 가상 설정 | R35: 별도 지정 없음 | S35: 기본 레시피 기준 | T35: images/M37.png | U35: M37-NA-ONE | V35: 하우스 레드와인, 얼음 없이 150ml 1잔, 대표 AI 연출 이미지 | W35: AI 연출 이미지 | X35: 주류 포함 | Y35: 필요 | Z35: 얼음 없이 150ml 1잔 | AA35: 부드러운 바디와 가벼운 떫은맛
A36: M23 | B36: 하우스 원두 200g | C36: 원두 | D36: House Blend Beans 200g | E36: 하우스 원두, 고소한 원두, House Blend Beans 200g | F36: 고소한 하우스 블렌드를 집에서도 즐길 수 있는 200g 홀빈 상품입니다. 분쇄하지 않은 원두로 제공합니다. | G36: 볶은 커피 원두 | H36: 레시피상 지정 재료 없음 | I36: 2 | J36: 1 | K36: 4 | L36: 4 | M36: 원두, 홀빈 | P36: R2 | Q36: 시연용 가상 설정 | R36: 별도 지정 없음 | S36: 원두를 추출했을 때의 향미 참고값 | T36: images/M23.png | U36: M23-NA-PACK | V36: 하우스 원두 200g, 200g 1봉, 대표 AI 연출 이미지 | W36: AI 연출 이미지 | X36: 해당 없음 | Y36: 해당 없음 | Z36: 200g 1봉 | AA36: 홀빈 상품
A37: M24 | B37: 에티오피아 원두 200g | C37: 원두 | D37: Ethiopia Beans 200g | E37: 싱글오리진 원두, 산미 있는 원두, Ethiopia Beans 200g | F37: 에티오피아 필터커피에 사용하는 원두의 200g 홀빈 상품입니다. 분쇄하지 않은 원두로 제공합니다. | G37: 볶은 커피 원두 | H37: 레시피상 지정 재료 없음 | I37: 2 | J37: 4 | K37: 2 | L37: 2 | M37: 원두, 홀빈 | P37: R3, R5 | Q37: 시연용 가상 설정 | R37: 별도 지정 없음 | S37: 원두를 추출했을 때의 향미 참고값 | T37: images/M24.png | U37: M24-NA-PACK | V37: 에티오피아 원두 200g, 200g 1봉, 대표 AI 연출 이미지 | W37: AI 연출 이미지 | X37: 해당 없음 | Y37: 해당 없음 | Z37: 200g 1봉 | AA37: 홀빈 상품
A38: M25 | B38: 디카페인 원두 200g | C38: 원두 | D38: Decaf Beans 200g | E38: 디카페인 원두, 콜롬비아 원두, Decaf Beans 200g | F38: 디카페인 커피에 사용하는 콜롬비아 원두의 200g 홀빈 상품입니다. 분쇄하지 않은 원두로 제공합니다. | G38: 볶은 디카페인 커피 원두 | H38: 레시피상 지정 재료 없음 | I38: 2 | J38: 2 | K38: 2 | L38: 3 | M38: 원두, 홀빈 | P38: R4, R5 | Q38: 시연용 가상 설정 | R38: 별도 지정 없음 | S38: 원두를 추출했을 때의 향미 참고값 | T38: images/M25.png | U38: M25-NA-PACK | V38: 디카페인 원두 200g, 200g 1봉, 대표 AI 연출 이미지 | W38: AI 연출 이미지 | X38: 해당 없음 | Y38: 해당 없음 | Z38: 200g 1봉 | AA38: 홀빈 상품

Sheet 가격영양
A2: 가격영양
A3: 52개 주문 단위 · 모든 주류 열량에 에탄올 포함 · 원액 2종과 희석 기준 구분
A5: 주문 단위 ID | B5: 메뉴명 | C5: 온도 | D5: 크기 | E5: 제공량(표준 구성) | F5: 단위 | G5: 가격(원) | H5: 열량(kcal) | I5: 탄수화물(g) | J5: 단백질(g) | K5: 지방(g) | L5: 당류(g) | M5: 나트륨(mg) | N5: 카페인(mg) | O5: 기본 샷 | P5: 에스프레소 외 카페인(mg) | Q5: 원두 ID | R5: 영양 기준 | S5: 에탄올(g) | T5: 도수(계산 기준) | U5: 계산 액체량(ml) | V5: 주류 원액1(ml) | W5: 원액1 도수 | X5: 배합 기준 | Y5: 주류 원액2(ml) | Z5: 원액2 도수
A6: M01-HOT-ONE | B6: 에스프레소 | C6: HOT | D6: ONE | E6: 60 | F6: ml | G6: 3500 | H6: =ROUND(I6*4+J6*4+K6*9+S6*7,0) -> 6 | I6: 1 | J6: 0.5 | K6: 0 | L6: 0 | M6: 5 | N6: 120 | O6: 2 | P6: 0 | Q6: B01 | R6: 가상 매장 시연용 설정. 실측·실제 브랜드 영양정보 아님 | S6: 0 | Y6: 0 | Z6: 0
A7: M02-HOT-S | B7: 아메리카노 | C7: HOT | D7: S | E7: 300 | F7: ml | G7: 4500 | H7: =ROUND(I7*4+J7*4+K7*9+S7*7,0) -> 6 | I7: 1 | J7: 0.5 | K7: 0 | L7: 0 | M7: 5 | N7: 120 | O7: 2 | P7: 0 | Q7: B01 | R7: 가상 매장 시연용 설정. 실측·실제 브랜드 영양정보 아님 | S7: 0 | Y7: 0 | Z7: 0
A8: M02-HOT-L | B8: 아메리카노 | C8: HOT | D8: L | E8: 400 | F8: ml | G8: 5500 | H8: =ROUND(I8*4+J8*4+K8*9+S8*7,0) -> 9 | I8: 1.5 | J8: 0.8 | K8: 0 | L8: 0 | M8: 8 | N8: 180 | O8: 3 | P8: 0 | Q8: B01 | R8: 가상 매장 시연용 설정. 실측·실제 브랜드 영양정보 아님 | S8: 0 | Y8: 0 | Z8: 0
A9: M02-ICED-S | B9: 아메리카노 | C9: ICED | D9: S | E9: 400 | F9: ml | G9: 4500 | H9: =ROUND(I9*4+J9*4+K9*9+S9*7,0) -> 6 | I9: 1 | J9: 0.5 | K9: 0 | L9: 0 | M9: 5 | N9: 120 | O9: 2 | P9: 0 | Q9: B01 | R9: 가상 매장 시연용 설정. 실측·실제 브랜드 영양정보 아님 | S9: 0 | Y9: 0 | Z9: 0
A10: M02-ICED-L | B10: 아메리카노 | C10: ICED | D10: L | E10: 500 | F10: ml | G10: 5500 | H10: =ROUND(I10*4+J10*4+K10*9+S10*7,0) -> 9 | I10: 1.5 | J10: 0.8 | K10: 0 | L10: 0 | M10: 8 | N10: 180 | O10: 3 | P10: 0 | Q10: B01 | R10: 가상 매장 시연용 설정. 실측·실제 브랜드 영양정보 아님 | S10: 0 | Y10: 0 | Z10: 0
A11: M03-HOT-S | B11: 카페 라떼 | C11: HOT | D11: S | E11: 240 | F11: ml | G11: 5500 | H11: =ROUND(I11*4+J11*4+K11*9+S11*7,0) -> 131 | I11: 10 | J11: 7 | K11: 7 | L11: 10 | M11: 90 | N11: 120 | O11: 2 | P11: 0 | Q11: B01 | R11: 가상 매장 시연용 설정. 실측·실제 브랜드 영양정보 아님 | S11: 0 | Y11: 0 | Z11: 0
A12: M03-HOT-L | B12: 카페 라떼 | C12: HOT | D12: L | E12: 340 | F12: ml | G12: 6500 | H12: =ROUND(I12*4+J12*4+K12*9+S12*7,0) -> 190 | I12: 15 | J12: 10 | K12: 10 | L12: 15 | M12: 135 | N12: 180 | O12: 3 | P12: 0 | Q12: B01 | R12: 가상 매장 시연용 설정. 실측·실제 브랜드 영양정보 아님 | S12: 0 | Y12: 0 | Z12: 0
A13: M03-ICED-S | B13: 카페 라떼 | C13: ICED | D13: S | E13: 360 | F13: ml | G13: 5500 | H13: =ROUND(I13*4+J13*4+K13*9+S13*7,0) -> 131 | I13: 10 | J13: 7 | K13: 7 | L13: 10 | M13: 90 | N13: 120 | O13: 2 | P13: 0 | Q13: B01 | R13: 가상 매장 시연용 설정. 실측·실제 브랜드 영양정보 아님 | S13: 0 | Y13: 0 | Z13: 0
A14: M03-ICED-L | B14: 카페 라떼 | C14: ICED | D14: L | E14: 460 | F14: ml | G14: 6500 | H14: =ROUND(I14*4+J14*4+K14*9+S14*7,0) -> 190 | I14: 15 | J14: 10 | K14: 10 | L14: 15 | M14: 135 | N14: 180 | O14: 3 | P14: 0 | Q14: B01 | R14: 가상 매장 시연용 설정. 실측·실제 브랜드 영양정보 아님 | S14: 0 | Y14: 0 | Z14: 0
A15: M04-HOT-ONE | B15: 카푸치노 | C15: HOT | D15: ONE | E15: 180 | F15: ml | G15: 5200 | H15: =ROUND(I15*4+J15*4+K15*9+S15*7,0) -> 93 | I15: 7 | J15: 5 | K15: 5 | L15: 7 | M15: 65 | N15: 120 | O15: 2 | P15: 0 | Q15: B01 | R15: 가상 매장 시연용 설정. 실측·실제 브랜드 영양정보 아님 | S15: 0 | Y15: 0 | Z15: 0
A16: M05-HOT-ONE | B16: 플랫화이트 | C16: HOT | D16: ONE | E16: 180 | F16: ml | G16: 5500 | H16: =ROUND(I16*4+J16*4+K16*9+S16*7,0) -> 93 | I16: 7 | J16: 5 | K16: 5 | L16: 7 | M16: 65 | N16: 120 | O16: 2 | P16: 0 | Q16: B01 | R16: 가상 매장 시연용 설정. 실측·실제 브랜드 영양정보 아님 | S16: 0 | Y16: 0 | Z16: 0
A17: M06-HOT-S | B17: 바닐라 라떼 | C17: HOT | D17: S | E17: 240 | F17: ml | G17: 6000 | H17: =ROUND(I17*4+J17*4+K17*9+S17*7,0) -> 191 | I17: 25 | J17: 7 | K17: 7 | L17: 24 | M17: 90 | N17: 120 | O17: 2 | P17: 0 | Q17: B01 | R17: 가상 매장 시연용 설정. 실측·실제 브랜드 영양정보 아님 | S17: 0 | Y17: 0 | Z17: 0
... A29: M12-ICED-ONE | B29: 디카페인 필터커피 | C29: ICED | D29: ONE | E29: 300 | F29: ml | G29: 6800 | H29: =ROUND(I29*4+J29*4+K29*9+S29*7,0) -> 6 | I29: 1 | J29: 0.5 | K29: 0 | L29: 0 | M29: 5 | N29: 8 | O29: 0 | P29: 0 | Q29: B03 | R29: 가상 매장 시연용 설정. 실측·실제 브랜드 영양정보 아님 | S29: 0 | Y29: 0 | Z29: 0
A30: M13-HOT-ONE | B30: 말차 라떼 | C30: HOT | D30: ONE | E30: 240 | F30: ml | G30: 6000 | H30: =ROUND(I30*4+J30*4+K30*9+S30*7,0) -> 191 | I30: 25 | J30: 7 | K30: 7 | L30: 22 | M30: 90 | N30: 70 | O30: 0 | P30: 70 | R30: 가상 매장 시연용 설정. 실측·실제 브랜드 영양정보 아님 | S30: 0 | Y30: 0 | Z30: 0
A31: M13-ICED-ONE | B31: 말차 라떼 | C31: ICED | D31: ONE | E31: 360 | F31: ml | G31: 6000 | H31: =ROUND(I31*4+J31*4+K31*9+S31*7,0) -> 191 | I31: 25 | J31: 7 | K31: 7 | L31: 22 | M31: 90 | N31: 70 | O31: 0 | P31: 70 | R31: 가상 매장 시연용 설정. 실측·실제 브랜드 영양정보 아님 | S31: 0 | Y31: 0 | Z31: 0
A32: M14-HOT-ONE | B32: 초코 라떼 | C32: HOT | D32: ONE | E32: 240 | F32: ml | G32: 5800 | H32: =ROUND(I32*4+J32*4+K32*9+S32*7,0) -> 229 | I32: 30 | J32: 7 | K32: 9 | L32: 26 | M32: 100 | N32: 12 | O32: 0 | P32: 12 | R32: 가상 매장 시연용 설정. 실측·실제 브랜드 영양정보 아님 | S32: 0 | Y32: 0 | Z32: 0
A33: M14-ICED-ONE | B33: 초코 라떼 | C33: ICED | D33: ONE | E33: 360 | F33: ml | G33: 5800 | H33: =ROUND(I33*4+J33*4+K33*9+S33*7,0) -> 229 | I33: 30 | J33: 7 | K33: 9 | L33: 26 | M33: 100 | N33: 12 | O33: 0 | P33: 12 | R33: 가상 매장 시연용 설정. 실측·실제 브랜드 영양정보 아님 | S33: 0 | Y33: 0 | Z33: 0
A34: M15-HOT-ONE | B34: 보성 홍차 밀크티 | C34: HOT | D34: ONE | E34: 240 | F34: ml | G34: 6000 | H34: =ROUND(I34*4+J34*4+K34*9+S34*7,0) -> 174 | I34: 24 | J34: 6 | K34: 6 | L34: 22 | M34: 80 | N34: 45 | O34: 0 | P34: 45 | R34: 가상 매장 시연용 설정. 실측·실제 브랜드 영양정보 아님 | S34: 0 | Y34: 0 | Z34: 0
A35: M15-ICED-ONE | B35: 보성 홍차 밀크티 | C35: ICED | D35: ONE | E35: 360 | F35: ml | G35: 6000 | H35: =ROUND(I35*4+J35*4+K35*9+S35*7,0) -> 174 | I35: 24 | J35: 6 | K35: 6 | L35: 22 | M35: 80 | N35: 45 | O35: 0 | P35: 45 | R35: 가상 매장 시연용 설정. 실측·실제 브랜드 영양정보 아님 | S35: 0 | Y35: 0 | Z35: 0
A36: M16-HOT-ONE | B36: 유자티 | C36: HOT | D36: ONE | E36: 300 | F36: ml | G36: 5500 | H36: =ROUND(I36*4+J36*4+K36*9+S36*7,0) -> 120 | I36: 30 | J36: 0 | K36: 0 | L36: 28 | M36: 5 | N36: 0 | O36: 0 | P36: 0 | R36: 가상 매장 시연용 설정. 실측·실제 브랜드 영양정보 아님 | S36: 0 | Y36: 0 | Z36: 0
A37: M16-ICED-ONE | B37: 유자티 | C37: ICED | D37: ONE | E37: 400 | F37: ml | G37: 5500 | H37: =ROUND(I37*4+J37*4+K37*9+S37*7,0) -> 120 | I37: 30 | J37: 0 | K37: 0 | L37: 28 | M37: 5 | N37: 0 | O37: 0 | P37: 0 | R37: 가상 매장 시연용 설정. 실측·실제 브랜드 영양정보 아님 | S37: 0 | Y37: 0 | Z37: 0
A38: M17-HOT-ONE | B38: 루이보스티 | C38: HOT | D38: ONE | E38: 300 | F38: ml | G38: 5000 | H38: =ROUND(I38*4+J38*4+K38*9+S38*7,0) -> 2 | I38: 0.5 | J38: 0 | K38: 0 | L38: 0 | M38: 3 | N38: 0 | O38: 0 | P38: 0 | R38: 가상 매장 시연용 설정. 실측·실제 브랜드 영양정보 아님 | S38: 0 | Y38: 0 | Z38: 0
A39: M17-ICED-ONE | B39: 루이보스티 | C39: ICED | D39: ONE | E39: 400 | F39: ml | G39: 5000 | H39: =ROUND(I39*4+J39*4+K39*9+S39*7,0) -> 2 | I39: 0.5 | J39: 0 | K39: 0 | L39: 0 | M39: 3 | N39: 0 | O39: 0 | P39: 0 | R39: 가상 매장 시연용 설정. 실측·실제 브랜드 영양정보 아님 | S39: 0 | Y39: 0 | Z39: 0
A40: M26-HOT-ONE | B40: 오미자차 | C40: HOT | D40: ONE | E40: 300 | F40: ml | G40: 6000 | H40: =ROUND(I40*4+J40*4+K40*9+S40*7,0) -> 112 | I40: 28 | J40: 0 | K40: 0 | L40: 26 | M40: 5 | N40: 0 | O40: 0 | P40: 0 | R40: 가상 매장 시연용 설정. 실측·실제 브랜드 영양정보 아님 | S40: 0 | Y40: 0 | Z40: 0
A41: M26-ICED-ONE | B41: 오미자차 | C41: ICED | D41: ONE | E41: 400 | F41: ml | G41: 6000 | H41: =ROUND(I41*4+J41*4+K41*9+S41*7,0) -> 112 | I41: 28 | J41: 0 | K41: 0 | L41: 26 | M41: 5 | N41: 0 | O41: 0 | P41: 0 | R41: 가상 매장 시연용 설정. 실측·실제 브랜드 영양정보 아님 | S41: 0 | Y41: 0 | Z41: 0
... A48: M29-NA-ONE | B48: 쑥인절미 4개 | C48: NA | D48: ONE | E48: 80 | F48: g | G48: 5500 | H48: =ROUND(I48*4+J48*4+K48*9+S48*7,0) -> 198 | I48: 40 | J48: 5 | K48: 2 | L48: 6 | M48: 60 | N48: 0 | O48: 0 | P48: 0 | R48: 가상 매장 시연용 설정. 실측·실제 브랜드 영양정보 아님 | S48: 0 | Y48: 0 | Z48: 0
A49: M32-ICED-ONE | B49: 유자 소주 하이볼 | C49: ICED | D49: ONE | E49: 300 | F49: ml | G49: 9500 | H49: =ROUND(I49*4+J49*4+K49*9+S49*7,0) -> 127 | I49: 18 | J49: 0 | K49: 0 | L49: 17 | M49: 8 | N49: 0 | O49: 0 | P49: 0 | R49: 가상 매장 시연용 설정. 실측·실제 브랜드 영양정보 아님 | S49: =ROUND((V49*W49+Y49*Z49)*0.789,2) -> 7.89 | T49: =(V49*W49+Y49*Z49)/U49 -> 0.052631579 | U49: 190 | V49: 50 | W49: 0.2 | X49: 소주 50ml + 유자청 30ml + 탄산수 110ml; 얼음 별도 | Y49: 0 | Z49: 0
A50: M33-ICED-ONE | B50: 오미자 소주 스프리츠 | C50: ICED | D50: ONE | E50: 300 | F50: ml | G50: 10000 | H50: =ROUND(I50*4+J50*4+K50*9+S50*7,0) -> 135 | I50: 20 | J50: 0 | K50: 0 | L50: 19 | M50: 8 | N50: 0 | O50: 0 | P50: 0 | R50: 가상 매장 시연용 설정. 실측·실제 브랜드 영양정보 아님 | S50: =ROUND((V50*W50+Y50*Z50)*0.789,2) -> 7.89 | T50: =(V50*W50+Y50*Z50)/U50 -> 0.05 | U50: 200 | V50: 50 | W50: 0.2 | X50: 소주 50ml + 오미자청 40ml + 탄산수 110ml; 얼음 별도 | Y50: 0 | Z50: 0
A51: M34-ICED-ONE | B51: 위스키 하이볼 | C51: ICED | D51: ONE | E51: 300 | F51: ml | G51: 9000 | H51: =ROUND(I51*4+J51*4+K51*9+S51*7,0) -> 101 | I51: 0.5 | J51: 0 | K51: 0 | L51: 0 | M51: 5 | N51: 0 | O51: 0 | P51: 0 | R51: 가상 매장 시연용 설정. 실측·실제 브랜드 영양정보 아님 | S51: =ROUND((V51*W51+Y51*Z51)*0.789,2) -> 14.2 | T51: =(V51*W51+Y51*Z51)/U51 -> 0.1 | U51: 180 | V51: 45 | W51: 0.4 | X51: 위스키 45ml(40%)+탄산수 135ml=180ml. 레몬 껍질·얼음 별도. 추가 얼음 희석 전 계산 | Y51: 0 | Z51: 0
A52: M35-ICED-ONE | B52: 에스프레소 마티니 | C52: ICED | D52: ONE | E52: 120 | F52: ml | G52: 12000 | H52: =ROUND(I52*4+J52*4+K52*9+S52*7,0) -> 182 | I52: 18 | J52: 0 | K52: 0 | L52: 17 | M52: 8 | N52: 70 | O52: 1 | P52: 10 | Q52: B01 | R52: 가상 매장 시연용 설정. 실측·실제 브랜드 영양정보 아님 | S52: =ROUND((V52*W52+Y52*Z52)*0.789,2) -> 15.78 | T52: =(V52*W52+Y52*Z52)/U52 -> 0.16666667 | U52: 120 | V52: 40 | W52: 0.4 | X52: 보드카 40ml(40%)+커피 리큐르 20ml(20%)+에스프레소 30ml+시럽 10ml+셰이킹 희석수 20ml=120ml. 얼음을 걸러 제공. 희석량은 가상값 | Y52: 20 | Z52: 0.2
A53: M36-ICED-ONE | B53: 라거 맥주 | C53: ICED | D53: ONE | E53: 330 | F53: ml | G53: 7000 | H53: =ROUND(I53*4+J53*4+K53*9+S53*7,0) -> 139 | I53: 11 | J53: 1 | K53: 0 | L53: 0.5 | M53: 13 | N53: 0 | O53: 0 | P53: 0 | R53: 가상 매장 시연용 설정. 실측·실제 브랜드 영양정보 아님 | S53: =ROUND((V53*W53+Y53*Z53)*0.789,2) -> 13.02 | T53: =(V53*W53+Y53*Z53)/U53 -> 0.05 | U53: 330 | V53: 330 | W53: 0.05 | X53: 5.0%로 설정한 가상 라거 330ml. 얼음·다른 재료·희석수 없음 | Y53: 0 | Z53: 0
A54: M37-NA-ONE | B54: 하우스 레드와인 | C54: NA | D54: ONE | E54: 150 | F54: ml | G54: 9000 | H54: =ROUND(I54*4+J54*4+K54*9+S54*7,0) -> 126 | I54: 4.5 | J54: 0 | K54: 0 | L54: 1 | M54: 8 | N54: 0 | O54: 0 | P54: 0 | R54: 가상 매장 시연용 설정. 실측·실제 브랜드 영양정보 아님 | S54: =ROUND((V54*W54+Y54*Z54)*0.789,2) -> 15.39 | T54: =(V54*W54+Y54*Z54)/U54 -> 0.13 | U54: 150 | V54: 150 | W54: 0.13 | X54: 13.0%로 설정한 가상 레드와인 150ml. 얼음·다른 재료·희석수 없음 | Y54: 0 | Z54: 0
A55: M23-NA-PACK | B55: 하우스 원두 200g | C55: NA | D55: PACK | E55: 200 | F55: g | G55: 16000 | O55: 0 | P55: 0 | Q55: B01 | R55: 음용 전 원두 상품. 1잔 영양값 해당 없음 | Y55: 0 | Z55: 0
A56: M24-NA-PACK | B56: 에티오피아 원두 200g | C56: NA | D56: PACK | E56: 200 | F56: g | G56: 19000 | O56: 0 | P56: 0 | Q56: B02 | R56: 음용 전 원두 상품. 1잔 영양값 해당 없음 | Y56: 0 | Z56: 0
A57: M25-NA-PACK | B57: 디카페인 원두 200g | C57: NA | D57: PACK | E57: 200 | F57: g | G57: 18000 | O57: 0 | P57: 0 | Q57: B03 | R57: 음용 전 원두 상품. 1잔 영양값 해당 없음 | Y57: 0 | Z57: 0

Sheet 원두
A2: 원두
A3: 원두 3종 · 산지·공정·맛·카페인은 모키의 시연용 설정
A5: 원두 ID | B5: 원두명 | C5: 산지 설정 | D5: 가공 설정 | E5: 로스팅 | F5: 맛 노트(재료 아님) | G5: 산미 1~5 | H5: 쓴맛 1~5 | I5: 바디 1~5 | J5: 디카페인 | K5: 카페인(mg/샷) | L5: 판매 메뉴 ID
A6: B01 | B6: 모키 하우스 블렌드 | C6: 브라질 70%, 콜롬비아 30% | D6: 내추럴·워시드 혼합 | E6: 미디엄 다크 | F6: 다크초콜릿, 구운 견과 | G6: 1 | H6: 4 | I6: 4 | J6: 아니오 | K6: 60 | L6: M23
A7: B02 | B7: 모키 에티오피아 싱글오리진 | C7: 에티오피아 | D7: 워시드 | E7: 미디엄 라이트 | F7: 감귤, 꽃, 홍차 | G7: 4 | H7: 2 | I7: 2 | J7: 아니오 | K7: 60 | L7: M24
A8: B03 | B8: 모키 콜롬비아 디카페인 | C8: 콜롬비아 | D8: 워시드 후 EA 디카페인 공정 | E8: 미디엄 | F8: 캐러멜, 코코아 | G8: 2 | H8: 2 | I8: 3 | J8: 예 | K8: 4 | L8: M25

Sheet 옵션규칙
A2: 옵션규칙
A3: 허용 목록만 적용 · 모든 주류는 고정 레시피·제공 방식 · 옵션 이름과 설명 한영 제공
A5: 옵션 ID | B5: 옵션명 | C5: 적용 메뉴 ID | D5: 입력 형식 | E5: 선택값과 추가금 | F5: 기본값 | G5: 제한 | H5: 변경 처리 | I5: 주요 영양 재산정 | J5: 적용 조건 | K5: English name | L5: English choices | M5: English restrictions | N5: English effects
A6: bean | B6: 원두 선택 | C6: M01, M02, M03, M04, M05, M06, M07, M08 | D6: choice | E6: B01: 하우스 +0원 B02: 에티오피아 싱글오리진 +1000원 B03: 콜롬비아 디카페인 +700원 | F6: B01 | G6: 필터커피와 콜드브루는 원두가 고정되어 있다. 원두 선택은 1종만 가능하며 추가금은 한 잔 기준이다. | H6: 선택 원두의 샷당 카페인 × (기본 샷 + 추가 샷) + 커피 외 카페인. 모카의 카카오 카페인은 유지 | I6: 기본값과 다른 선택 시 미산정 | J6: 적용 메뉴 확인 | K6: Coffee bean | L6: B01: House blend +0 KRW B02: Ethiopian single origin +1000 KRW B03: Colombian decaf +700 KRW | M6: Choose one bean. Surcharge is per cup. Filter coffee and cold brew use fixed beans. | N6: Caffeine = selected bean caffeine per shot × total shots + caffeine from other sources.
A7: extra_shots | B7: 샷 추가 | C7: M01, M02, M03, M04, M05, M06, M07, M08 | D7: integer | E7: 0~2, 회당 600원 | F7: 0 | G7: 콜드브루·필터·논커피·디저트 불가. 추가 샷도 선택한 원두 사용 | H7: 추가금과 카페인을 횟수만큼 반영 | I7: 기본값과 다른 선택 시 미산정 | J7: 적용 메뉴 확인 | K7: Extra espresso shots | L7: 0–2, 600 KRW each | M7: 0 to 2 extra shots, for supported espresso drinks only. | N7: 600 KRW per extra shot; the selected bean is also used for extra shots.
A8: milk | B8: 우유 변경 | C8: M03, M04, M05, M06, M10, M13, M15 | D8: choice | E8: dairy: 일반 우유 +0원 lowfat: 저지방 우유 +0원 oat: 오트 음료 +500원 soy: 두유 +500원 | F8: dairy | G8: 크림 라떼·모카·초코는 고정 레시피로 우유 변경 미지원. 우유 없음 요청은 별도 비유제품 메뉴 제안 | H8: 원재료 중 우유만 선택한 음료로 바꾸고, 알레르기 목록에서도 우유만 해당 재료로 교체한다. 저지방: 우유 유지, 오트: 귀리, 두유: 대두. 다른 성분과 공용기구 안내는 유지한다. | I8: 기본값과 다른 선택 시 미산정 | J8: 적용 메뉴 확인 | K8: Milk choice | L8: dairy: Regular milk +0 KRW lowfat: Low-fat milk +0 KRW oat: Oat drink +500 KRW soy: Soy drink +500 KRW | M8: Available only for listed menus. Cream latte, mocha and chocolate have fixed recipes. | N8: Replace only milk and its allergen entry. Retain other ingredients and the shared-equipment notice.
A9: sweetness | B9: 시럽·유자청 양 | C9: M06, M16 | D9: choice | E9: normal: 기본 +0원 less: 절반 +0원 | F9: normal | G9: 바닐라 시럽 또는 유자청을 절반으로 줄인다. 단맛과 당류가 정확히 절반이 되거나 무당·제로가 되는 것은 아니다. 다른 음료는 고정 레시피다. | H9: 열량·당류의 변경 후 정확값 미산정. 기본 레시피 영양값을 변경 후 수치로 재사용하지 않음 | I9: 기본값과 다른 선택 시 미산정 | J9: 적용 메뉴 확인 | K9: Syrup amount | L9: normal: Regular +0 KRW less: Half syrup +0 KRW | M9: Only vanilla latte and yuja tea. Half syrup does not mean half of all sugar. | N9: Modified nutrition is not calculated.
A10: ice | B10: 얼음 양 | C10: M02, M03, M06, M07, M08, M09, M10, M11, M12, M13, M14, M15, M16, M17, M26, M27 | D10: choice | E10: normal: 기본 +0원 less: 적게 +0원 | F10: normal | G10: ICED 주문 단위의 적용 메뉴만 허용. 모든 주류·얼음 없음·얼음 종류 변경은 미지원 | H10: 얼음을 줄여도 우유·물·커피를 더 채우지 않는다. 컵에 담기는 전체 부피만 줄어들며, 기본 레시피의 주요 영양과 카페인은 유지한다. | I10: 기본값 유지 | J10: ICED만 | K10: Ice amount | L10: normal: Regular ice +0 KRW less: Less ice +0 KRW | M10: ICED variants of listed non-alcohol menus only. Alcoholic drinks have fixed serving conditions. | N10: Less ice does not add more drink. Base nutrition stays the same.
A11: warming | B11: 데우기 | C11: M18 | D11: choice | E11: room: 기본 +0원 warm: 따뜻하게 +0원 | F11: room | G11: 버터 소금빵만 선택 가능. 다른 디저트는 고정 제공 방식 | H11: 추가 요금 없음. 기본 레시피의 주요 영양값은 유지한다. | I11: 기본값 유지 | J11: 적용 메뉴 확인 | K11: Warm the bread | L11: room: As served +0 KRW warm: Warmed +0 KRW | M11: Only the butter salt bread. Other food has fixed serving conditions. | N11: No surcharge; base nutrition stays the same.

Sheet 매장정책
A2: 매장정책
A3: 주류 확인·언어 전환을 포함한 19개 시연 규칙 · 실제 앱 구현 완료 아님
A5: 정책 ID | B5: 주제 | C5: 구분 | D5: 내용 | E5: English policy
A6: P01 | B6: 컨셉 | C6: 시연 설정 | D6: 취향과 언어에 맞춰 커피·차·디저트·주류를 선택하는 테이블 주문 커피바. 한국 재료 메뉴도 일반 분류에 통합한다. 언어와 취향은 따로 확인한다. 실제 브랜드와 제휴하지 않은 가상 매장이다. | E6: Moki is a fictional table-order coffee bar offering coffee, tea, desserts and alcoholic drinks. Korean ingredients appear within the regular categories. Ask language and taste preferences separately. No brand affiliation.
A7: P02 | B7: 좌석 | C7: 개발 연동 규칙 | D7: 시연용 좌석 번호는 1~12다. 설정된 좌석을 화면에서 확인하고 주문에 table_id로 저장한다. 번호는 정수로 검증하며, 이 데이터만으로 기기별 자동 연결이 구현되는 것은 아니다. | E7: Demo tables are integers 1 through 12. Confirm the displayed table before saving table_id. This dataset does not bind devices to tables.
A8: P03 | B8: 온도·크기 | C8: 검증 규칙 | D8: 목록에 있는 온도·크기만 지원한다. ONE은 단일 크기, PACK은 200g 홀빈이다. ICED는 차갑게 제공한다는 코드이며 M35 마티니·M36 맥주는 얼음이 없다. M37 와인의 NA는 온도 선택이 없다는 뜻이다. 미지원 선택은 자동 대체하지 않는다. 하이볼만 요청하면 유자 소주 하이볼과 위스키 하이볼 중 선택을 확인한다. | E8: Use only listed variants. ONE is one size; PACK is a 200 g whole-bean bag. ICED means served cold, not necessarily over ice: M35 and M36 are served without ice. NA for M37 means no temperature choice. Ask before substituting unsupported choices. For a request for just a highball, ask the guest to choose yuja soju or whisky.
A9: P04 | B9: 이용·수령 | C9: 시연 설정 | D9: 매장 이용·좌석 수령이 기본이다. 비주류는 요청 시 포장한다. 모든 주류는 매장 이용만 가능하다. 포장비·개인컵 할인은 시연에서 제공하지 않는다. | E9: Dine-in table service is the default. Non-alcohol items may be packed on request. All alcoholic drinks are dine-in only. No packaging surcharge or reusable-cup discount in the demo.
A10: P05 | B10: 주문 확정 | C10: 개발 연동 규칙 | D10: 좌석·품목·온도·크기·옵션·수량·합계를 확인한 뒤 시연 주문을 확정한다. 주류가 있으면 해당 손님에 대한 직원 확인 전에는 pending_staff_check 상태로 둔다. 실제 결제·접수 성공을 주장하지 않는다. | E10: Confirm table, items, temperature, size, options, quantities and total. An alcohol order stays pending_staff_check until staff verify the intended drinker. Never claim a real payment or venue receipt succeeded.
A11: P06 | B11: 추가 주문 | C11: 개발 연동 규칙 | D11: 확정 뒤 추가 주문은 같은 좌석에 연결된 새 주문으로 만든다. 확정된 과거 주문을 덮어쓰지 않는다. 이전 주문 다시 담기도 새 장바구니에서 확인 후 확정한다. | E11: Additional orders are new orders for the same table. Never overwrite a confirmed order. Reordering uses a new cart and requires confirmation.
A12: P07 | B12: 미지원 | C12: 미지원 안내 | D12: 실제 결제, 분할 결제, 영수증 발급, 포인트 적립, 쿠폰·기프티콘, 예약, 실시간 재고·제조 진행·대기시간 연동은 미지원이다. 지원된다고 답하지 않는다. | E12: Real payments, split payments, receipts, points, coupons, reservations, live stock and preparation-time integration are not implemented.
A13: P08 | B13: 도움 | C13: 안내만 제공 | D13: 상담은 바리스타에게 직접 문의하도록 안내한다. 직원 호출 API가 구현되지 않았다면 호출을 보냈다고 답하지 않는다. 언어·화면 접근성 기능도 구현 상태를 따라 설명한다. | E13: Ask the barista directly for help. Do not claim a staff-call API or accessibility function has run unless implemented.
A14: P09 | B14: 성분·알레르기 | C14: 레시피 정보 | D14: 원재료·알레르기 유발 재료는 가상 레시피다. 공용기구 교차접촉 가능성을 배제하지 않는다. 약과의 밀·보리·참깨, 인절미의 대두, 라거의 보리, 와인의 아황산류를 표시한다. 우유 변경은 해당 항목만 교체한다. 비건·할랄·글루텐 프리 인증을 추정하지 않는다. | E14: Ingredients are fictional recipe data. Shared equipment may cause cross-contact. Yakgwa contains wheat, barley and sesame; rice cakes contain soy; lager contains barley; wine contains sulfites. Replace only milk-related entries for a milk change. Do not claim vegan, halal or gluten-free certification.
A15: P10 | B15: 영양·카페인 | C15: 시연 설정 | D15: 영양·카페인은 실측이 아닌 시연값이다. 원두·샷·우유·시럽을 바꾸면 주요 영양은 미산정, 카페인은 별도 계산한다. 얼음·데우기만 바꾸면 기본 영양을 유지한다. 디카페인은 카페인 0이 아니다. 모든 주류 열량에 에탄올 7kcal/g를 포함한다. 에스프레소 마티니는 주류이며 카페인 70mg으로 설정했다. 주류 미첨가는 0% 인증이 아니다. | E15: Nutrition and caffeine are demo estimates. Bean, shot, milk or syrup changes invalidate major nutrition; caffeine is calculated separately. Ice and warming alone retain base nutrition. Decaf is not caffeine-free. All alcoholic drinks include 7 kcal per gram of ethanol. Espresso Martini is alcoholic and has modeled caffeine of 70 mg. No alcohol added is not certified 0% ABV.
A16: P11 | B16: 가격·수량 | C16: 개발 연동 규칙 | D16: 원화 정수, 부가세 포함 시연 가격. 품목 수량은 1~10 정수. 단가=(주문단위 가격+선택형 옵션 추가금+추가 샷 수×600), 소계=단가×수량. 필수 조건 누락 시 확인 질문, 유효성 검증 전 장바구니 변경 금지. | E16: Prices are whole KRW including demo VAT. Quantities must be integers 1–10. Unit price = variant price + choice surcharges + extra shots × 600 KRW. Validate before changing the cart.
... A24: P19 | B24: 도수·배합 | C24: 계산 기준 | D24: 도수는 원액별 부피×도수를 합산한 순알코올 부피÷계산 기준 액체량이다. M32·M33·M34는 추가 얼음 희석 전, M35는 가정한 셰이킹 희석수 20ml 포함이다. 맥주·와인은 설정 도수를 그대로 쓴다. 질량은 순알코올 ml×0.789g/ml, 열량은 반올림한 질량×7kcal/g 포함. 안전 음주량이나 실제 제품 분석값이 아니다. | E24: Sum volume × ABV across alcohol components, then divide by the modeled liquid volume. M32, M33 and M34 exclude further ice melt; M35 includes 20 ml of modeled shaking dilution. Beer and wine use their assigned ABV. Ethanol mass uses 0.789 g/ml and energy uses the rounded mass × 7 kcal/g. These are recipe estimates, not measured products or safe-drinking thresholds.

Sheet 검증질문
A2: 검증질문
A3: 47개 팀 연동 시험안 · 기대값이며 실제 RAG 통과 결과가 아님
A5: 질문 ID | B5: 유형 | C5: 테스트 질문 | D5: 기대 처리 | E5: 실행 상태
A6: Q01 | B6: 추천 | C6: 산미 적고 고소한 커피랑 빵 추천해줘 | D6: M02 하우스+M18. 맛 점수·원두 설명을 근거로 제안, 장바구니 자동 추가 금지 | E6: 팀 앱에서 실행 전
A7: Q02 | B7: 복합질의 | C7: 아메리카노랑 카푸치노 가격·진하기 차이는? | D7: 아메리카노 S 4500, 카푸치노 5200. 블랙커피와 우유 거품 차이 설명. 진함을 카페인과 혼동하지 않음 | E7: 팀 앱에서 실행 전
A8: Q03 | B8: 복합주문 | C8: 따뜻한 디카페인 라떼랑 약과 한 접시 주세요 | D8: 라떼 S/L 확인. S 1잔+B03=6200, M28 1접시(2개)=4500, 합계10700. 수량·좌석 확인 | E8: 팀 앱에서 실행 전
A9: Q04 | B9: 금액 | C9: 아이스 라떼 큰 거 디카페인에 오트, 샷 두 번 더, 두 잔 | D9: M03-ICED-L 6500+700+500+1200=8900/잔, 2잔17800. 카페인 시연값20mg/잔 | E9: 팀 앱에서 실행 전
A10: Q05 | B10: 불가옵션 | C10: 콜드브루 디카페인으로 바꾸고 샷 추가해줘 | D10: 두 옵션 미지원. 디카페인 아메리카노 또는 필터커피 제안 후 확인 | E10: 팀 앱에서 실행 전
A11: Q06 | B11: 온도 | C11: 카푸치노 아이스로 주세요 | D11: HOT 단일 크기만 가능. ICED 라떼를 대안으로 제시하고 확인 전 대체 금지 | E11: 팀 앱에서 실행 전
A12: Q07 | B12: 사이즈 | C12: 아메리카노 XL로 | D12: S/L만 제공. 지원 크기와 가격을 설명하고 선택 확인 | E12: 팀 앱에서 실행 전
A13: Q08 | B13: 성분 | C13: 카페인 없는 말차라떼 주세요 | D13: 말차 카페인 시연값70mg. 루이보스·유자티 대안. 논커피를 무카페인으로 취급하지 않음 | E13: 팀 앱에서 실행 전
A14: Q09 | B14: 카페인 | C14: 디카페인 모카는 카페인 0이죠? | D14: 커피8+카카오12=20mg 시연값. 0 보장 불가 | E14: 팀 앱에서 실행 전
A15: Q10 | B15: 알레르기 | C15: 우유 알레르기 있는데 크림 라떼를 오트로 바꿔줘 | D15: 크림 라떼 우유변경 미지원. 다른 성분·공용기구 확인 안내, 안전하다고 단정 금지 | E15: 팀 앱에서 실행 전
A16: Q11 | B16: 성분변경 | C16: 라떼 두유로 바꾸면 알레르기가 없어져요? | D16: 가상 레시피 우유→대두로 변경. 대두 포함 및 공용기구 안내. 무알레르기 보장 금지 | E16: 팀 앱에서 실행 전
... A52: Q47 | B52: 모호한 별칭 | C52: 하이볼 하나 주세요 / One highball, please. | D52: M32 유자 소주 하이볼과 M34 위스키 하이볼 중 선택 확인. 기본 메뉴를 임의 확정하지 않음 | E52: 팀 앱에서 실행 전

Sheet 선별내역
A2: 선별내역
A3: 원본 86개 메뉴 선별의 역사 기록 · 새 메뉴 ID 열은 v1 당시 연결, 현재 판매 여부는 오른쪽 확인
A5: 원메뉴 행 | B5: 이전 메뉴명 | C5: 이전 분류 | D5: 기존 행 수 | E5: 처리 | F5: 새 메뉴 ID | G5: 새 메뉴명 | H5: 이유 | I5: v4 판매 반영 | J5: v4 검토
A6: 3 | B6: 자몽·망고 요거트 컵빙수 | C6: [백억빙수] 사계절 내내 먹고 또 먹어 | D6: 1 | E6: 배포 메뉴에서 제외 | H6: 빙수·스무디 전용 제조 범위와 유사한 맛 변형을 줄임 | I6: 기존 제외 유지 | J6: 원본 선별 기록 보존
A7: 4 | B7: 우유 팥 컵빙수 | C7: [백억빙수] 사계절 내내 먹고 또 먹어 | D7: 1 | E7: 배포 메뉴에서 제외 | H7: 빙수·스무디 전용 제조 범위와 유사한 맛 변형을 줄임 | I7: 기존 제외 유지 | J7: 원본 선별 기록 보존
A8: 11 | B8: 구름 아메리카노 | C8: [시즌 한정] 취향대로 즐기는 썸머드링크 | D8: 1 | E8: 배포 메뉴에서 제외 | H8: 맛·재료가 겹치는 변형을 줄이고 핵심 커피·논커피·페어링 메뉴에 집중 | I8: 기존 제외 유지 | J8: 원본 선별 기록 보존
A9: 12 | B9: 제로 복숭아아이스티 | C9: [NEW] 백억 제로픽 모음 | D9: 1 | E9: 배포 메뉴에서 제외 | H9: 맛·재료가 겹치는 변형을 줄이고 핵심 커피·논커피·페어링 메뉴에 집중 | I9: 기존 제외 유지 | J9: 원본 선별 기록 보존
A10: 15 | B10: 고운결 라떼 | C10: [10BILLION SIGNATURE] | D10: 2 | E10: 재설계하여 활용 | F10: M07 | G10: 고운결 크림 라떼 | H10: 기존 이름을 살려 크림 커피로 재설계. 레시피·크기·가격·수치는 새 설정 | I10: 유지 | J10: 원본 선별 기록 보존
A11: 16 | B11: 고운결 초코 라떼 | C11: [10BILLION SIGNATURE] | D11: 2 | E11: 배포 메뉴에서 제외 | H11: 맛·재료가 겹치는 변형을 줄이고 핵심 커피·논커피·페어링 메뉴에 집중 | I11: 기존 제외 유지 | J11: 원본 선별 기록 보존
A12: 17 | B12: 고운결 말차 라떼 | C12: [10BILLION SIGNATURE] | D12: 2 | E12: 배포 메뉴에서 제외 | H12: 맛·재료가 겹치는 변형을 줄이고 핵심 커피·논커피·페어링 메뉴에 집중 | I12: 기존 제외 유지 | J12: 원본 선별 기록 보존
A13: 37 | B13: 땅콩버터 오징어 (몸통) | C13: [백억 시네마] 시네마 메뉴.ZIP | D13: 1 | E13: 배포 메뉴에서 제외 | H13: 식사·분식·영화 간식은 커피 시음과 페어링 중심 컨셉에서 제외 | I13: 기존 제외 유지 | J13: 원본 선별 기록 보존
A14: 38 | B14: 칠리치즈 나초 | C14: [백억 시네마] 시네마 메뉴.ZIP | D14: 1 | E14: 배포 메뉴에서 제외 | H14: 식사·분식·영화 간식은 커피 시음과 페어링 중심 컨셉에서 제외 | I14: 기존 제외 유지 | J14: 원본 선별 기록 보존
A15: 39 | B15: 플레인 핫도그 | C15: [백억 시네마] 시네마 메뉴.ZIP | D15: 1 | E15: 배포 메뉴에서 제외 | H15: 식사·분식·영화 간식은 커피 시음과 페어링 중심 컨셉에서 제외 | I15: 기존 제외 유지 | J15: 원본 선별 기록 보존
A16: 40 | B16: 칠리치즈 핫도그 | C16: [백억 시네마] 시네마 메뉴.ZIP | D16: 1 | E16: 배포 메뉴에서 제외 | H16: 식사·분식·영화 간식은 커피 시음과 페어링 중심 컨셉에서 제외 | I16: 기존 제외 유지 | J16: 원본 선별 기록 보존
A17: 41 | B17: 김치볶음밥 | C17: [백억 볶음밥] 백억 볶음밥 3종 | D17: 1 | E17: 배포 메뉴에서 제외 | H17: 식사·분식·영화 간식은 커피 시음과 페어링 중심 컨셉에서 제외 | I17: 기존 제외 유지 | J17: 원본 선별 기록 보존
A18: 42 | B18: 새우볶음밥 | C18: [백억 볶음밥] 백억 볶음밥 3종 | D18: 1 | E18: 배포 메뉴에서 제외 | H18: 식사·분식·영화 간식은 커피 시음과 페어링 중심 컨셉에서 제외 | I18: 기존 제외 유지 | J18: 원본 선별 기록 보존
A19: 43 | B19: 대패삼겹볶음밥 | C19: [백억 볶음밥] 백억 볶음밥 3종 | D19: 1 | E19: 배포 메뉴에서 제외 | H19: 식사·분식·영화 간식은 커피 시음과 페어링 중심 컨셉에서 제외 | I19: 기존 제외 유지 | J19: 원본 선별 기록 보존
A20: 44 | B20: 겹결 호두과자 (5개) | C20: [백억 휴게소] 휴게소 분식 코너 | D20: 1 | E20: 배포 메뉴에서 제외 | H20: 식사·분식·영화 간식은 커피 시음과 페어링 중심 컨셉에서 제외 | I20: 기존 제외 유지 | J20: 원본 선별 기록 보존
A21: 45 | B21: 매콤 떡볶이 | C21: [백억 휴게소] 휴게소 분식 코너 | D21: 1 | E21: 배포 메뉴에서 제외 | H21: 식사·분식·영화 간식은 커피 시음과 페어링 중심 컨셉에서 제외 | I21: 기존 제외 유지 | J21: 원본 선별 기록 보존
A22: 46 | B22: 바삭 감자 치즈볼 | C22: [백억 휴게소] 휴게소 분식 코너 | D22: 1 | E22: 배포 메뉴에서 제외 | H22: 식사·분식·영화 간식은 커피 시음과 페어링 중심 컨셉에서 제외 | I22: 기존 제외 유지 | J22: 원본 선별 기록 보존
... A27: 51 | B27: 벨지움 초코무스 케이크 | C27: [케이크 & 다쿠아즈] 홈 카페 디저트 | D27: 1 | E27: 배포 메뉴에서 제외 | H27: 맛·재료가 겹치는 변형을 줄이고 핵심 커피·논커피·페어링 메뉴에 집중 | I27: 기존 제외 유지 | J27: 원본 선별 기록 보존
A28: 52 | B28: 까망베르 치즈 케이크 | C28: [케이크 & 다쿠아즈] 홈 카페 디저트 | D28: 1 | E28: 재설계하여 활용 | F28: M20 | G28: 바스크 치즈케이크 | H28: 바스크 치즈케이크로 재설계. 기존 알레르기·영양을 승계하지 않음 | I28: 유지 | J28: 원본 선별 기록 보존
A29: 53 | B29: 티라미수 미니 홀 케이크 | C29: [케이크 & 다쿠아즈] 홈 카페 디저트 | D29: 1 | E29: 재설계하여 활용 | F29: M21 | G29: 티라미수 컵 | H29: 홀 케이크를 개인용 컵으로 변경. 중량·레시피·수치는 새 설정 | I29: 유지 | J29: 원본 선별 기록 보존
A30: 54 | B30: 더블치즈 미니 홀 케이크 | C30: [케이크 & 다쿠아즈] 홈 카페 디저트 | D30: 1 | E30: 배포 메뉴에서 제외 | H30: 맛·재료가 겹치는 변형을 줄이고 핵심 커피·논커피·페어링 메뉴에 집중 | I30: 기존 제외 유지 | J30: 원본 선별 기록 보존
A31: 55 | B31: 황치즈 다쿠아즈 | C31: [케이크 & 다쿠아즈] 홈 카페 디저트 | D31: 1 | E31: 재설계하여 활용 | F31: M22 | G31: 황치즈 다쿠아즈 | H31: 작은 페어링 디저트로 유지. 아몬드 포함 레시피를 명시적으로 새로 설정 | I31: 현재 판매 제외 | J31: 기존 기록은 보존. M22 판매 제외; 자동 주문 치환 금지
A32: 56 | B32: 앙버터 다쿠아즈 | C32: [케이크 & 다쿠아즈] 홈 카페 디저트 | D32: 1 | E32: 배포 메뉴에서 제외 | H32: 맛·재료가 겹치는 변형을 줄이고 핵심 커피·논커피·페어링 메뉴에 집중 | I32: 기존 제외 유지 | J32: 원본 선별 기록 보존
A33: 57 | B33: 순수우유 다쿠아즈 | C33: [케이크 & 다쿠아즈] 홈 카페 디저트 | D33: 1 | E33: 배포 메뉴에서 제외 | H33: 맛·재료가 겹치는 변형을 줄이고 핵심 커피·논커피·페어링 메뉴에 집중 | I33: 기존 제외 유지 | J33: 원본 선별 기록 보존
A34: 58 | B34: 초코크런치 다쿠아즈 | C34: [케이크 & 다쿠아즈] 홈 카페 디저트 | D34: 1 | E34: 배포 메뉴에서 제외 | H34: 맛·재료가 겹치는 변형을 줄이고 핵심 커피·논커피·페어링 메뉴에 집중 | I34: 기존 제외 유지 | J34: 원본 선별 기록 보존
A35: 59 | B35: 초코 바게트 | C35: [베이커리] 홈 베이커리 디저트 | D35: 1 | E35: 배포 메뉴에서 제외 | H35: 맛·재료가 겹치는 변형을 줄이고 핵심 커피·논커피·페어링 메뉴에 집중 | I35: 기존 제외 유지 | J35: 원본 선별 기록 보존
A36: 61 | B36: 연유 버터떡 | C36: [베이커리] 홈 베이커리 디저트 | D36: 2 | E36: 배포 메뉴에서 제외 | H36: 맛·재료가 겹치는 변형을 줄이고 핵심 커피·논커피·페어링 메뉴에 집중 | I36: 기존 제외 유지 | J36: 원본 선별 기록 보존
A37: 62 | B37: 미니 마들렌(레몬/초코) | C37: [베이커리] 홈 베이커리 디저트 | D37: 2 | E37: 재설계하여 활용 | F37: M19 | G37: 레몬 마들렌 2개 | H37: 레몬만 채택, 9개 묶음을 2개 접시로 축소. 초코 변형 제외 | I37: 현재 판매 제외 | J37: 기존 기록은 보존. M19 판매 제외; 자동 주문 치환 금지
A38: 63 | B38: 우유크림 카스테라 | C38: [베이커리] 홈 베이커리 디저트 | D38: 1 | E38: 배포 메뉴에서 제외 | H38: 맛·재료가 겹치는 변형을 줄이고 핵심 커피·논커피·페어링 메뉴에 집중 | I38: 기존 제외 유지 | J38: 원본 선별 기록 보존
A39: 64 | B39: 초코 크림 카스테라 | C39: [베이커리] 홈 베이커리 디저트 | D39: 1 | E39: 배포 메뉴에서 제외 | H39: 맛·재료가 겹치는 변형을 줄이고 핵심 커피·논커피·페어링 메뉴에 집중 | I39: 기존 제외 유지 | J39: 원본 선별 기록 보존
A40: 65 | B40: 한입 슈 (10개) | C40: [베이커리] 홈 베이커리 디저트 | D40: 1 | E40: 배포 메뉴에서 제외 | H40: 맛·재료가 겹치는 변형을 줄이고 핵심 커피·논커피·페어링 메뉴에 집중 | I40: 기존 제외 유지 | J40: 원본 선별 기록 보존
A41: 67 | B41: 소금크림 찰깨빵 | C41: [베이커리] 홈 베이커리 디저트 | D41: 1 | E41: 배포 메뉴에서 제외 | H41: 맛·재료가 겹치는 변형을 줄이고 핵심 커피·논커피·페어링 메뉴에 집중 | I41: 기존 제외 유지 | J41: 원본 선별 기록 보존
A42: 68 | B42: 크로크무슈 | C42: [베이커리] 홈 베이커리 디저트 | D42: 1 | E42: 배포 메뉴에서 제외 | H42: 맛·재료가 겹치는 변형을 줄이고 핵심 커피·논커피·페어링 메뉴에 집중 | I42: 기존 제외 유지 | J42: 원본 선별 기록 보존
A43: 69 | B43: 커피향 번 | C43: [베이커리] 홈 베이커리 디저트 | D43: 1 | E43: 배포 메뉴에서 제외 | H43: 맛·재료가 겹치는 변형을 줄이고 핵심 커피·논커피·페어링 메뉴에 집중 | I43: 기존 제외 유지 | J43: 원본 선별 기록 보존
A44: 70 | B44: 버터 소금빵 | C44: [베이커리] 홈 베이커리 디저트 | D44: 1 | E44: 재설계하여 활용 | F44: M18 | G44: 버터 소금빵 | H44: 기존 메뉴 유형을 활용하되 레시피·제공량·가격·영양을 모키용으로 통일 | I44: 유지 | J44: 원본 선별 기록 보존
A45: 73 | B45: 초코떡 | C45: [베이커리] 홈 베이커리 디저트 | D45: 1 | E45: 배포 메뉴에서 제외 | H45: 맛·재료가 겹치는 변형을 줄이고 핵심 커피·논커피·페어링 메뉴에 집중 | I45: 기존 제외 유지 | J45: 원본 선별 기록 보존
A46: 87 | B46: 카페라떼 | C46: [커피] 커피 메뉴 (카페인) | D46: 2 | E46: 재설계하여 활용 | F46: M03 | G46: 카페 라떼 | H46: 기존 메뉴 유형을 활용하되 레시피·제공량·가격·영양을 모키용으로 통일 | I46: 유지 | J46: 원본 선별 기록 보존
...

Sheet 설계근거
A2: 설계근거
A3: 참고처 11개 · IBA 칵테일 구조 참고 추가 · 배합·영양·가격은 별도 시연값
A5: 참고 ID | B5: 참고처 | C5: 공식 URL | D5: 확인한 구성·사실 | E5: 모키에 적용한 점 | F5: 출처의 한계 | G5: 확인일
A6: R1 | B6: 리사르 | C6: https://leesarcoffee.com/category/introduce/ | D6: 에이미 원두를 쓰는 에스프레소·블랙·플랫화이트·라떼 소개 | E6: 기본 에스프레소 메뉴를 작게 구성 | F6: 공식 검색 색인 확인. 개별 글 직접 열기는 403. 현재 가격·영양은 채택하지 않음 | G6: 2026-10-14
A7: R2 | B7: 프릳츠 | C7: https://fritz.co.kr/product/list.html?cate_no=25 | D7: 산미가 다른 블렌드 3종과 200g 원두 판매 | E7: 고소한 하우스와 산뜻한 원두를 비교하고 소매 원두로 연결 | F7: 공식 페이지 직접 확인. 브랜드명·상품명·가격을 모키에 복사하지 않음 | G7: 2026-10-14
A8: R3 | B8: 펠트 | C8: https://feltcoffee.com/ | D8: 싱글오리진의 산지·가공·로스팅과 디카페인 구분 | E8: 원두 설명 필드를 정하고 디카페인을 원두 옵션으로 관리 | F8: 공식 페이지 직접 확인. 원두 세부 설정은 새로 작성 | G8: 2026-10-14
A9: R4 | B9: 커피리브레 | C9: https://coffeelibre.kr/product/list.html?cate_no=60 | D9: 중약배전부터 강배전, 디카페인 블렌드의 구분 | E9: 산미·쓴맛·바디감과 디카페인을 별개 속성으로 관리 | F9: 공식 페이지 직접 확인. 실제 상품 재고·판매 상태를 모키에 적용하지 않음 | G9: 2026-10-14
A10: R5 | B10: 나무사이로 | C10: https://namusairo.com/ | D10: 원산지·맛 노트·디카프 상품 정보 | E10: 필터커피의 원두 설명과 음용 후 원두 구매 연결 | F10: 공식 페이지 직접 확인. 맛 노트의 과일·견과 표현은 원재료가 아님 | G10: 2026-10-14
A11: R6 | B11: 뜰안 / 한국관광공사 | C11: https://english.visitkorea.or.kr/svc/contents/contentsView.do?vcontsId=186462 | D11: 전통차·쑥떡 등 다과와 커피를 함께 소개 | E11: 커피와 함께 차·다과를 선택하는 구성. 차/논커피·디저트로 통합 | F11: 관광 소개의 구성만 참고. 효능·레시피·가격을 채택하지 않음 | G11: 2026-10-14
A12: R7 | B12: 오설록 | C12: https://www.osulloc.com/kr/ko/shop/item/teahouse | D12: 차·티라떼·차 기반 아이스 음료·디저트 구성 | E12: 차/논커피 분류 안의 차·티라떼 선택지 | F12: 공식 메뉴 구조 참고. 브랜드 제품·사진·가격은 복사하지 않음 | G12: 2026-10-14
A13: R8 | B13: 바 참 / 서울관광재단 | C13: https://english.visitseoul.net/partners-en/luxurytour/KoreanCocktailKocktail/ENN033260 | D13: 한국 술과 지역 재료를 활용한 칵테일 소개 | E13: 유자·오미자 칵테일의 재료 활용 영감. 주류 전체는 클래식 칵테일·맥주·와인으로 확장 | F13: 2020년 소개. 현재 판매 메뉴·가격·레시피 근거가 아님 | G13: 2026-10-14
A14: R9 | B14: 국가법령정보센터 | C14: https://www.law.go.kr/lsInfoP.do?lsId=000815 | D14: 청소년 보호법 제2조·제28조의 청소년 판매 금지 및 나이·본인 확인 | E14: 직원 확인 대기 상태를 주문 규칙에 반영 | F14: 영업 인허가·매장별 운영 적법성 전체 검토 아님. 자동 신원 확인을 구현한 것이 아님 | G14: 2026-10-14
A15: R10 | B15: European Commission | C15: https://knowledge-for-policy.ec.europa.eu/alcoholic-beverages_en | D15: 에탄올 에너지 환산 7kcal/g | E15: 칵테일 열량에 알코올 에너지 포함 | F15: 레시피 수치는 가상값. 에탄올 밀도 0.789g/ml는 시연 근삿값 | G15: 2026-10-14
A16: R11 | B16: International Bartenders Association | C16: https://iba-world.com/iba-cocktail/espresso-martini/ | D16: 보드카·커피 리큐르·시럽·에스프레소를 흔들어 거르고 커피 원두로 장식 | E16: 커피바와 주류를 연결하는 에스프레소 마티니. 재료 역할과 제공 방식 참고 | F16: IBA의 정확한 비율을 재현하지 않음. 모키의 40/20/30/10ml 배합·희석수·도수·카페인·가격은 별도 가상 설정. 브랜드·사진 복사 없음 | G16: 2026-10-14

Sheet 사진메뉴판
B2: 모키 · 커피와 술을 함께 고르는 커피바
B3: MOKI / Coffee, tea, desserts & drinks
B4: 커피 · 차/논커피 · 디저트 · 주류 · 원두 / 33 menus · AI representative images
B20: =INDEX(메뉴목록!$B$6:$B$38,MATCH("M01",메뉴목록!$A$6:$A$38,0)) -> 에스프레소 | G20: =INDEX(메뉴목록!$B$6:$B$38,MATCH("M02",메뉴목록!$A$6:$A$38,0)) -> 아메리카노 | L20: =INDEX(메뉴목록!$B$6:$B$38,MATCH("M03",메뉴목록!$A$6:$A$38,0)) -> 카페 라떼
B21: =INDEX(한영안내!$C$6:$C$38,MATCH("M01",한영안내!$A$6:$A$38,0)) -> Espresso | G21: =INDEX(한영안내!$C$6:$C$38,MATCH("M02",한영안내!$A$6:$A$38,0)) -> Americano | L21: =INDEX(한영안내!$C$6:$C$38,MATCH("M03",한영안내!$A$6:$A$38,0)) -> Caffe Latte
B23: =MIN(INDEX(가격영양!$G$6:$G$57,MATCH("M01-HOT-ONE",가격영양!$A$6:$A$57,0))) -> 3500 | D23: M01 | E23: M01 | G23: =MIN(INDEX(가격영양!$G$6:$G$57,MATCH("M02-HOT-S",가격영양!$A$6:$A$57,0)),INDEX(가격영양!$G$6:$G$57,MATCH("M02-HOT-L",가격영양!$A$6:$A$57,0)),INDEX(가격영양!$G$6:$G$57,MATCH("M02-ICED-S",가격영양!$A$6:$A$57,0)),INDEX(가격영양!$G$6:$G$57,MATCH("M02-ICED-L",가격영양!$A$6:$A$57,0))) -> 4500 | I23: M02 | J23: M02 | L23: =MIN(INDEX(가격영양!$G$6:$G$57,MATCH("M03-HOT-S",가격영양!$A$6:$A$57,0)),INDEX(가격영양!$G$6:$G$57,MATCH("M03-HOT-L",가격영양!$A$6:$A$57,0)),INDEX(가격영양!$G$6:$G$57,MATCH("M03-ICED-S",가격영양!$A$6:$A$57,0)),INDEX(가격영양!$G$6:$G$57,MATCH("M03-ICED-L",가격영양!$A$6:$A$57,0))) -> 5500 | N23: M03 | O23: M03
B24: one cup | C24: one cup | D24: one cup | E24: one cup | G24: one cup | H24: one cup | I24: one cup | J24: one cup | L24: one cup | M24: one cup | N24: one cup | O24: one cup
B25: 사진 / Photo: HOT / one size | C25: 사진 / Photo: HOT / one size | D25: 사진 / Photo: HOT / one size | E25: 사진 / Photo: HOT / one size | G25: 사진 / Photo: ICED / S | H25: 사진 / Photo: ICED / S | I25: 사진 / Photo: ICED / S | J25: 사진 / Photo: ICED / S | L25: 사진 / Photo: HOT / S | M25: 사진 / Photo: HOT / S | N25: 사진 / Photo: HOT / S | O25: 사진 / Photo: HOT / S
B40: =INDEX(메뉴목록!$B$6:$B$38,MATCH("M04",메뉴목록!$A$6:$A$38,0)) -> 카푸치노 | G40: =INDEX(메뉴목록!$B$6:$B$38,MATCH("M05",메뉴목록!$A$6:$A$38,0)) -> 플랫화이트 | L40: =INDEX(메뉴목록!$B$6:$B$38,MATCH("M06",메뉴목록!$A$6:$A$38,0)) -> 바닐라 라떼
B41: =INDEX(한영안내!$C$6:$C$38,MATCH("M04",한영안내!$A$6:$A$38,0)) -> Cappuccino | G41: =INDEX(한영안내!$C$6:$C$38,MATCH("M05",한영안내!$A$6:$A$38,0)) -> Flat White | L41: =INDEX(한영안내!$C$6:$C$38,MATCH("M06",한영안내!$A$6:$A$38,0)) -> Vanilla Latte
B43: =MIN(INDEX(가격영양!$G$6:$G$57,MATCH("M04-HOT-ONE",가격영양!$A$6:$A$57,0))) -> 5200 | D43: M04 | E43: M04 | G43: =MIN(INDEX(가격영양!$G$6:$G$57,MATCH("M05-HOT-ONE",가격영양!$A$6:$A$57,0))) -> 5500 | I43: M05 | J43: M05 | L43: =MIN(INDEX(가격영양!$G$6:$G$57,MATCH("M06-HOT-S",가격영양!$A$6:$A$57,0)),INDEX(가격영양!$G$6:$G$57,MATCH("M06-HOT-L",가격영양!$A$6:$A$57,0)),INDEX(가격영양!$G$6:$G$57,MATCH("M06-ICED-S",가격영양!$A$6:$A$57,0)),INDEX(가격영양!$G$6:$G$57,MATCH("M06-ICED-L",가격영양!$A$6:$A$57,0))) -> 6000 | N43: M06 | O43: M06
B44: one cup | C44: one cup | D44: one cup | E44: one cup | G44: one cup | H44: one cup | I44: one cup | J44: one cup | L44: one cup | M44: one cup | N44: one cup | O44: one cup
B45: 사진 / Photo: HOT / one size | C45: 사진 / Photo: HOT / one size | D45: 사진 / Photo: HOT / one size | E45: 사진 / Photo: HOT / one size | G45: 사진 / Photo: HOT / one size | H45: 사진 / Photo: HOT / one size | I45: 사진 / Photo: HOT / one size | J45: 사진 / Photo: HOT / one size | L45: 사진 / Photo: ICED / S | M45: 사진 / Photo: ICED / S | N45: 사진 / Photo: ICED / S | O45: 사진 / Photo: ICED / S
B60: =INDEX(메뉴목록!$B$6:$B$38,MATCH("M07",메뉴목록!$A$6:$A$38,0)) -> 고운결 크림 라떼 | G60: =INDEX(메뉴목록!$B$6:$B$38,MATCH("M08",메뉴목록!$A$6:$A$38,0)) -> 다크 카페 모카 | L60: =INDEX(메뉴목록!$B$6:$B$38,MATCH("M09",메뉴목록!$A$6:$A$38,0)) -> 콜드브루
B61: =INDEX(한영안내!$C$6:$C$38,MATCH("M07",한영안내!$A$6:$A$38,0)) -> Goungyeol Cream Latte | G61: =INDEX(한영안내!$C$6:$C$38,MATCH("M08",한영안내!$A$6:$A$38,0)) -> Dark Caffe Mocha | L61: =INDEX(한영안내!$C$6:$C$38,MATCH("M09",한영안내!$A$6:$A$38,0)) -> Cold Brew
B63: =MIN(INDEX(가격영양!$G$6:$G$57,MATCH("M07-ICED-ONE",가격영양!$A$6:$A$57,0))) -> 6500 | D63: M07 | E63: M07 | G63: =MIN(INDEX(가격영양!$G$6:$G$57,MATCH("M08-HOT-ONE",가격영양!$A$6:$A$57,0)),INDEX(가격영양!$G$6:$G$57,MATCH("M08-ICED-ONE",가격영양!$A$6:$A$57,0))) -> 6200 | I63: M08 | J63: M08 | L63: =MIN(INDEX(가격영양!$G$6:$G$57,MATCH("M09-ICED-ONE",가격영양!$A$6:$A$57,0))) -> 5200 | N63: M09 | O63: M09
B64: one cup | C64: one cup | D64: one cup | E64: one cup | G64: one cup | H64: one cup | I64: one cup | J64: one cup | L64: one cup | M64: one cup | N64: one cup | O64: one cup
B65: 사진 / Photo: ICED / one size | C65: 사진 / Photo: ICED / one size | D65: 사진 / Photo: ICED / one size | E65: 사진 / Photo: ICED / one size | G65: 사진 / Photo: HOT / one size | H65: 사진 / Photo: HOT / one size | I65: 사진 / Photo: HOT / one size | J65: 사진 / Photo: HOT / one size | L65: 사진 / Photo: ICED / one size | M65: 사진 / Photo: ICED / one size | N65: 사진 / Photo: ICED / one size | O65: 사진 / Photo: ICED / one size
B80: =INDEX(메뉴목록!$B$6:$B$38,MATCH("M10",메뉴목록!$A$6:$A$38,0)) -> 콜드브루 라떼 | G80: =INDEX(메뉴목록!$B$6:$B$38,MATCH("M11",메뉴목록!$A$6:$A$38,0)) -> 에티오피아 필터커피 | L80: =INDEX(메뉴목록!$B$6:$B$38,MATCH("M12",메뉴목록!$A$6:$A$38,0)) -> 디카페인 필터커피
B81: =INDEX(한영안내!$C$6:$C$38,MATCH("M10",한영안내!$A$6:$A$38,0)) -> Cold Brew Latte | G81: =INDEX(한영안내!$C$6:$C$38,MATCH("M11",한영안내!$A$6:$A$38,0)) -> Ethiopia Filter Coffee | L81: =INDEX(한영안내!$C$6:$C$38,MATCH("M12",한영안내!$A$6:$A$38,0)) -> Decaf Filter Coffee
B83: =MIN(INDEX(가격영양!$G$6:$G$57,MATCH("M10-ICED-ONE",가격영양!$A$6:$A$57,0))) -> 6000 | D83: M10 | E83: M10 | G83: =MIN(INDEX(가격영양!$G$6:$G$57,MATCH("M11-HOT-ONE",가격영양!$A$6:$A$57,0)),INDEX(가격영양!$G$6:$G$57,MATCH("M11-ICED-ONE",가격영양!$A$6:$A$57,0))) -> 6500 | I83: M11 | J83: M11 | L83: =MIN(INDEX(가격영양!$G$6:$G$57,MATCH("M12-HOT-ONE",가격영양!$A$6:$A$57,0)),INDEX(가격영양!$G$6:$G$57,MATCH("M12-ICED-ONE",가격영양!$A$6:$A$57,0))) -> 6800 | N83: M12 | O83: M12
B84: one cup | C84: one cup | D84: one cup | E84: one cup | G84: one cup | H84: one cup | I84: one cup | J84: one cup | L84: one cup | M84: one cup | N84: one cup | O84: one cup
B85: 사진 / Photo: ICED / one size | C85: 사진 / Photo: ICED / one size | D85: 사진 / Photo: ICED / one size | E85: 사진 / Photo: ICED / one size | G85: 사진 / Photo: HOT / one size | H85: 사진 / Photo: HOT / one size | I85: 사진 / Photo: HOT / one size | J85: 사진 / Photo: HOT / one size | L85: 사진 / Photo: HOT / one size | M85: 사진 / Photo: HOT / one size | N85: 사진 / Photo: HOT / one size | O85: 사진 / Photo: HOT / one size
B100: =INDEX(메뉴목록!$B$6:$B$38,MATCH("M13",메뉴목록!$A$6:$A$38,0)) -> 말차 라떼 | G100: =INDEX(메뉴목록!$B$6:$B$38,MATCH("M14",메뉴목록!$A$6:$A$38,0)) -> 초코 라떼 | L100: =INDEX(메뉴목록!$B$6:$B$38,MATCH("M15",메뉴목록!$A$6:$A$38,0)) -> 보성 홍차 밀크티
B101: =INDEX(한영안내!$C$6:$C$38,MATCH("M13",한영안내!$A$6:$A$38,0)) -> Matcha Latte | G101: =INDEX(한영안내!$C$6:$C$38,MATCH("M14",한영안내!$A$6:$A$38,0)) -> Chocolate Latte | L101: =INDEX(한영안내!$C$6:$C$38,MATCH("M15",한영안내!$A$6:$A$38,0)) -> Boseong Black Milk Tea
B103: =MIN(INDEX(가격영양!$G$6:$G$57,MATCH("M13-HOT-ONE",가격영양!$A$6:$A$57,0)),INDEX(가격영양!$G$6:$G$57,MATCH("M13-ICED-ONE",가격영양!$A$6:$A$57,0))) -> 6000 | D103: M13 | E103: M13 | G103: =MIN(INDEX(가격영양!$G$6:$G$57,MATCH("M14-HOT-ONE",가격영양!$A$6:$A$57,0)),INDEX(가격영양!$G$6:$G$57,MATCH("M14-ICED-ONE",가격영양!$A$6:$A$57,0))) -> 5800 | I103: M14 | J103: M14 | L103: =MIN(INDEX(가격영양!$G$6:$G$57,MATCH("M15-HOT-ONE",가격영양!$A$6:$A$57,0)),INDEX(가격영양!$G$6:$G$57,MATCH("M15-ICED-ONE",가격영양!$A$6:$A$57,0))) -> 6000 | N103: M15 | O103: M15
B104: one cup | C104: one cup | D104: one cup | E104: one cup | G104: one cup | H104: one cup | I104: one cup | J104: one cup | L104: one cup | M104: one cup | N104: one cup | O104: one cup
B105: 사진 / Photo: ICED / one size | C105: 사진 / Photo: ICED / one size | D105: 사진 / Photo: ICED / one size | E105: 사진 / Photo: ICED / one size | G105: 사진 / Photo: HOT / one size | H105: 사진 / Photo: HOT / one size | I105: 사진 / Photo: HOT / one size | J105: 사진 / Photo: HOT / one size | L105: 사진 / Photo: ICED / one size | M105: 사진 / Photo: ICED / one size | N105: 사진 / Photo: ICED / one size | O105: 사진 / Photo: ICED / one size
B120: =INDEX(메뉴목록!$B$6:$B$38,MATCH("M16",메뉴목록!$A$6:$A$38,0)) -> 유자티 | G120: =INDEX(메뉴목록!$B$6:$B$38,MATCH("M17",메뉴목록!$A$6:$A$38,0)) -> 루이보스티 | L120: =INDEX(메뉴목록!$B$6:$B$38,MATCH("M26",메뉴목록!$A$6:$A$38,0)) -> 오미자차
B121: =INDEX(한영안내!$C$6:$C$38,MATCH("M16",한영안내!$A$6:$A$38,0)) -> Yuja Tea — Korean Citrus | G121: =INDEX(한영안내!$C$6:$C$38,MATCH("M17",한영안내!$A$6:$A$38,0)) -> Rooibos Tea | L121: =INDEX(한영안내!$C$6:$C$38,MATCH("M26",한영안내!$A$6:$A$38,0)) -> Omija Tea — Five-Flavor Berry
B123: =MIN(INDEX(가격영양!$G$6:$G$57,MATCH("M16-HOT-ONE",가격영양!$A$6:$A$57,0)),INDEX(가격영양!$G$6:$G$57,MATCH("M16-ICED-ONE",가격영양!$A$6:$A$57,0))) -> 5500 | D123: M16 | E123: M16 | G123: =MIN(INDEX(가격영양!$G$6:$G$57,MATCH("M17-HOT-ONE",가격영양!$A$6:$A$57,0)),INDEX(가격영양!$G$6:$G$57,MATCH("M17-ICED-ONE",가격영양!$A$6:$A$57,0))) -> 5000 | I123: M17 | J123: M17 | L123: =MIN(INDEX(가격영양!$G$6:$G$57,MATCH("M26-HOT-ONE",가격영양!$A$6:$A$57,0)),INDEX(가격영양!$G$6:$G$57,MATCH("M26-ICED-ONE",가격영양!$A$6:$A$57,0))) -> 6000 | N123: M26 | O123: M26
B124: one cup | C124: one cup | D124: one cup | E124: one cup | G124: one cup | H124: one cup | I124: one cup | J124: one cup | L124: one cup | M124: one cup | N124: one cup | O124: one cup
B125: 사진 / Photo: ICED / one size | C125: 사진 / Photo: ICED / one size | D125: 사진 / Photo: ICED / one size | E125: 사진 / Photo: ICED / one size | G125: 사진 / Photo: HOT / one size | H125: 사진 / Photo: HOT / one size | I125: 사진 / Photo: HOT / one size | J125: 사진 / Photo: HOT / one size | L125: 사진 / Photo: ICED / one size | M125: 사진 / Photo: ICED / one size | N125: 사진 / Photo: ICED / one size | O125: 사진 / Photo: ICED / one size
B140: =INDEX(메뉴목록!$B$6:$B$38,MATCH("M27",메뉴목록!$A$6:$A$38,0)) -> 대추생강차 | G140: =INDEX(메뉴목록!$B$6:$B$38,MATCH("M18",메뉴목록!$A$6:$A$38,0)) -> 버터 소금빵 | L140: =INDEX(메뉴목록!$B$6:$B$38,MATCH("M20",메뉴목록!$A$6:$A$38,0)) -> 바스크 치즈케이크
B141: =INDEX(한영안내!$C$6:$C$38,MATCH("M27",한영안내!$A$6:$A$38,0)) -> Daechu Saenggang Tea — Jujube & Ginger | G141: =INDEX(한영안내!$C$6:$C$38,MATCH("M18",한영안내!$A$6:$A$38,0)) -> Butter Salt Bread | L141: =INDEX(한영안내!$C$6:$C$38,MATCH("M20",한영안내!$A$6:$A$38,0)) -> Basque Cheesecake
B143: =MIN(INDEX(가격영양!$G$6:$G$57,MATCH("M27-HOT-ONE",가격영양!$A$6:$A$57,0)),INDEX(가격영양!$G$6:$G$57,MATCH("M27-ICED-ONE",가격영양!$A$6:$A$57,0))) -> 6500 | D143: M27 | E143: M27 | G143: =MIN(INDEX(가격영양!$G$6:$G$57,MATCH("M18-NA-ONE",가격영양!$A$6:$A$57,0))) -> 3800 | I143: M18 | J143: M18 | L143: =MIN(INDEX(가격영양!$G$6:$G$57,MATCH("M20-NA-ONE",가격영양!$A$6:$A$57,0))) -> 6800 | N143: M20 | O143: M20
B144: one cup | C144: one cup | D144: one cup | E144: one cup | G144: one bread roll | H144: one bread roll | I144: one bread roll | J144: one bread roll | L144: one slice | M144: one slice | N144: one slice | O144: one slice
B145: 사진 / Photo: HOT / one size | C145: 사진 / Photo: HOT / one size | D145: 사진 / Photo: HOT / one size | E145: 사진 / Photo: HOT / one size | G145: 사진 / Photo: 빵 1개 | H145: 사진 / Photo: 빵 1개 | I145: 사진 / Photo: 빵 1개 | J145: 사진 / Photo: 빵 1개 | L145: 사진 / Photo: 케이크 1조각 | M145: 사진 / Photo: 케이크 1조각 | N145: 사진 / Photo: 케이크 1조각 | O145: 사진 / Photo: 케이크 1조각
B160: =INDEX(메뉴목록!$B$6:$B$38,MATCH("M21",메뉴목록!$A$6:$A$38,0)) -> 티라미수 컵 | G160: =INDEX(메뉴목록!$B$6:$B$38,MATCH("M28",메뉴목록!$A$6:$A$38,0)) -> 약과 2개 | L160: =INDEX(메뉴목록!$B$6:$B$38,MATCH("M29",메뉴목록!$A$6:$A$38,0)) -> 쑥인절미 4개
B161: =INDEX(한영안내!$C$6:$C$38,MATCH("M21",한영안내!$A$6:$A$38,0)) -> Tiramisu Cup | G161: =INDEX(한영안내!$C$6:$C$38,MATCH("M28",한영안내!$A$6:$A$38,0)) -> Yakgwa — Honey Cookies (2 pcs) | L161: =INDEX(한영안내!$C$6:$C$38,MATCH("M29",한영안내!$A$6:$A$38,0)) -> Ssuk Injeolmi — Mugwort Rice Cakes (4 pcs)
...

Sheet 한영안내
A2: 한영 메뉴 안내 / Bilingual Menu Guide
A3: 영어로 맛·식감·성분·판매 단위 설명 · 41행 아래 재료 용어집
A5: 메뉴 ID | B5: 한국어 이름 | C5: English name | D5: English description | E5: Ingredients | F5: Allergen ingredients | G5: Texture | H5: Culture note | I5: Order unit | J5: Alcohol status | K5: Image alt text
A6: M01 | B6: 에스프레소 | C6: Espresso | D6: A double espresso served in a small cup, with a bold aroma and lingering finish. | E6: coffee beans, water | F6: None specified; cross-contact possible | G6: Short and intense | I6: one cup | J6: No alcohol added in recipe | K6: Espresso, HOT / one cup, representative AI-generated image
